Workbook

Sheet INPUT
A1: HORARIOS DE SALIDA — Tren Urquiza
A2: ⚠️ Editar SOLO los horarios en esta hoja. El script lee únicamente esta pestaña.
A4: DL_weekday | Lunes a Viernes → Lacroze
A5: Variable | B5: Nº | C5: Horario
A6: DL_weekday | B6: 1 | C6: 0.041666667
A7: DL_weekday | B7: 2 | C7: 02:30
A8: DL_weekday | B8: 3 | C8: 03:45
A9: DL_weekday | B9: 4 | C9: 04:30
A10: DL_weekday | B10: 5 | C10: 04:45
A11: DL_weekday | B11: 6 | C11: 05:00
A12: DL_weekday | B12: 7 | C12: 05:15
A13: DL_weekday | B13: 8 | C13: 05:30
A14: DL_weekday | B14: 9 | C14: 05:40
A15: DL_weekday | B15: 10 | C15: 05:51
A16: DL_weekday | B16: 11 | C16: 06:01
A17: DL_weekday | B17: 12 | C17: 06:11
A18: DL_weekday | B18: 13 | C18: 06:21
... A98: DL_weekday | B98: 93 | C98: 23:59
A100: DL_saturday | Sábados → Lacroze
A101: Variable | B101: Nº | C101: Horario
A102: DL_saturday | B102: 1 | C102: 01:00
A103: DL_saturday | B103: 2 | C103: 02:30
A104: DL_saturday | B104: 3 | C104: 03:45
A105: DL_saturday | B105: 4 | C105: 04:30
A106: DL_saturday | B106: 5 | C106: 05:00
A107: DL_saturday | B107: 6 | C107: 05:30
A108: DL_saturday | B108: 7 | C108: 05:52
A109: DL_saturday | B109: 8 | C109: 06:12
A110: DL_saturday | B110: 9 | C110: 06:32
A111: DL_saturday | B111: 10 | C111: 06:52
A112: DL_saturday | B112: 11 | C112: 07:07
A113: DL_saturday | B113: 12 | C113: 07:22
... A165: DL_saturday | B165: 64 | C165: 23:48
A167: DL_sunday | Domingos → Lacroze
A168: Variable | B168: Nº | C168: Horario
A169: DL_sunday | B169: 1 | C169: 00:01
A170: DL_sunday | B170: 2 | C170: 03:12
A171: DL_sunday | B171: 3 | C171: 04:15
A172: DL_sunday | B172: 4 | C172: 05:30
A173: DL_sunday | B173: 5 | C173: 06:20
...

Sheet LM_Semana
A1: Tren Urquiza — Lunes a Viernes → Lacroze
A2: Salida desde General Lemos | Horario Mural Invierno 2026 — Metrovías
A4: Estación | B4: {=INDEX(INPUT!$C:$C, 6+COLUMN()-2)} -> 0.041666667 | C4: {=INDEX(INPUT!$C:$C, 6+COLUMN()-2)} -> 02:30 | D4: {=INDEX(INPUT!$C:$C, 6+COLUMN()-2)} -> 03:45 | E4: {=INDEX(INPUT!$C:$C, 6+COLUMN()-2)} -> 04:30 | F4: {=INDEX(INPUT!$C:$C, 6+COLUMN()-2)} -> 04:45 | G4: {=INDEX(INPUT!$C:$C, 6+COLUMN()-2)} -> 05:00 | H4: {=INDEX(INPUT!$C:$C, 6+COLUMN()-2)} -> 05:15 | I4: {=INDEX(INPUT!$C:$C, 6+COLUMN()-2)} -> 05:30 | ... CP4: {=INDEX(INPUT!$C:$C, 6+COLUMN()-2)} -> 23:59
A5: General Lemos | B5: =B4 -> 0.041666667 | C5: =C4 -> 02:30 | D5: =D4 -> 03:45 | E5: =E4 -> 04:30 | F5: =F4 -> 04:45 | G5: =G4 -> 05:00 | H5: =H4 -> 05:15 | I5: =I4 -> 05:30 | ... CP5: =CP4 -> 23:59
A6: Sargento Cabral | B6: =TEXT(MOD(TIMEVALUE(B5)+2/1440,1),"HH:MM") -> 01:02 | C6: =TEXT(MOD(TIMEVALUE(C5)+2/1440,1),"HH:MM") -> 02:32 | D6: =TEXT(MOD(TIMEVALUE(D5)+2/1440,1),"HH:MM") -> 03:47 | E6: =TEXT(MOD(TIMEVALUE(E5)+2/1440,1),"HH:MM") -> 04:32 | F6: =TEXT(MOD(TIMEVALUE(F5)+2/1440,1),"HH:MM") -> 04:47 | G6: =TEXT(MOD(TIMEVALUE(G5)+2/1440,1),"HH:MM") -> 05:02 | H6: =TEXT(MOD(TIMEVALUE(H5)+2/1440,1),"HH:MM") -> 05:17 | I6: =TEXT(MOD(TIMEVALUE(I5)+2/1440,1),"HH:MM") -> 05:32 | ... CP6: =TEXT(MOD(TIMEVALUE(CP5)+2/1440,1),"HH:MM") -> 00:01
A7: Campo de Mayo | B7: =TEXT(MOD(TIMEVALUE(B5)+4/1440,1),"HH:MM") -> 01:04 | C7: =TEXT(MOD(TIMEVALUE(C5)+4/1440,1),"HH:MM") -> 02:34 | D7: =TEXT(MOD(TIMEVALUE(D5)+4/1440,1),"HH:MM") -> 03:49 | E7: =TEXT(MOD(TIMEVALUE(E5)+4/1440,1),"HH:MM") -> 04:34 | F7: =TEXT(MOD(TIMEVALUE(F5)+4/1440,1),"HH:MM") -> 04:49 | G7: =TEXT(MOD(TIMEVALUE(G5)+4/1440,1),"HH:MM") -> 05:04 | H7: =TEXT(MOD(TIMEVALUE(H5)+4/1440,1),"HH:MM") -> 05:19 | I7: =TEXT(MOD(TIMEVALUE(I5)+4/1440,1),"HH:MM") -> 05:34 | ... CP7: =TEXT(MOD(TIMEVALUE(CP5)+4/1440,1),"HH:MM") -> 00:03
A8: Teniente Agneta | B8: =TEXT(MOD(TIMEVALUE(B5)+5/1440,1),"HH:MM") -> 01:05 | C8: =TEXT(MOD(TIMEVALUE(C5)+5/1440,1),"HH:MM") -> 02:35 | D8: =TEXT(MOD(TIMEVALUE(D5)+5/1440,1),"HH:MM") -> 03:50 | E8: =TEXT(MOD(TIMEVALUE(E5)+5/1440,1),"HH:MM") -> 04:35 | F8: =TEXT(MOD(TIMEVALUE(F5)+5/1440,1),"HH:MM") -> 04:50 | G8: =TEXT(MOD(TIMEVALUE(G5)+5/1440,1),"HH:MM") -> 05:05 | H8: =TEXT(MOD(TIMEVALUE(H5)+5/1440,1),"HH:MM") -> 05:20 | I8: =TEXT(MOD(TIMEVALUE(I5)+5/1440,1),"HH:MM") -> 05:35 | ... CP8: =TEXT(MOD(TIMEVALUE(CP5)+5/1440,1),"HH:MM") -> 00:04
A9: Capitán Lozano | B9: =TEXT(MOD(TIMEVALUE(B5)+7/1440,1),"HH:MM") -> 01:07 | C9: =TEXT(MOD(TIMEVALUE(C5)+7/1440,1),"HH:MM") -> 02:37 | D9: =TEXT(MOD(TIMEVALUE(D5)+7/1440,1),"HH:MM") -> 03:52 | E9: =TEXT(MOD(TIMEVALUE(E5)+7/1440,1),"HH:MM") -> 04:37 | F9: =TEXT(MOD(TIMEVALUE(F5)+7/1440,1),"HH:MM") -> 04:52 | G9: =TEXT(MOD(TIMEVALUE(G5)+7/1440,1),"HH:MM") -> 05:07 | H9: =TEXT(MOD(TIMEVALUE(H5)+7/1440,1),"HH:MM") -> 05:22 | I9: =TEXT(MOD(TIMEVALUE(I5)+7/1440,1),"HH:MM") -> 05:37 | ... CP9: =TEXT(MOD(TIMEVALUE(CP5)+7/1440,1),"HH:MM") -> 00:06
A10: Sgto. Barruffaldi | B10: =TEXT(MOD(TIMEVALUE(B5)+9/1440,1),"HH:MM") -> 01:09 | C10: =TEXT(MOD(TIMEVALUE(C5)+9/1440,1),"HH:MM") -> 02:39 | D10: =TEXT(MOD(TIMEVALUE(D5)+9/1440,1),"HH:MM") -> 03:54 | E10: =TEXT(MOD(TIMEVALUE(E5)+9/1440,1),"HH:MM") -> 04:39 | F10: =TEXT(MOD(TIMEVALUE(F5)+9/1440,1),"HH:MM") -> 04:54 | G10: =TEXT(MOD(TIMEVALUE(G5)+9/1440,1),"HH:MM") -> 05:09 | H10: =TEXT(MOD(TIMEVALUE(H5)+9/1440,1),"HH:MM") -> 05:24 | I10: =TEXT(MOD(TIMEVALUE(I5)+9/1440,1),"HH:MM") -> 05:39 | ... CP10: =TEXT(MOD(TIMEVALUE(CP5)+9/1440,1),"HH:MM") -> 00:08
A11: Juan E. de la Salle | B11: =TEXT(MOD(TIMEVALUE(B5)+12/1440,1),"HH:MM") -> 01:12 | C11: =TEXT(MOD(TIMEVALUE(C5)+12/1440,1),"HH:MM") -> 02:42 | D11: =TEXT(MOD(TIMEVALUE(D5)+12/1440,1),"HH:MM") -> 03:57 | E11: =TEXT(MOD(TIMEVALUE(E5)+12/1440,1),"HH:MM") -> 04:42 | F11: =TEXT(MOD(TIMEVALUE(F5)+12/1440,1),"HH:MM") -> 04:57 | G11: =TEXT(MOD(TIMEVALUE(G5)+12/1440,1),"HH:MM") -> 05:12 | H11: =TEXT(MOD(TIMEVALUE(H5)+12/1440,1),"HH:MM") -> 05:27 | I11: =TEXT(MOD(TIMEVALUE(I5)+12/1440,1),"HH:MM") -> 05:42 | ... CP11: =TEXT(MOD(TIMEVALUE(CP5)+12/1440,1),"HH:MM") -> 00:11
A12: Ejército de los Andes | B12: =TEXT(MOD(TIMEVALUE(B5)+14/1440,1),"HH:MM") -> 01:14 | C12: =TEXT(MOD(TIMEVALUE(C5)+14/1440,1),"HH:MM") -> 02:44 | D12: =TEXT(MOD(TIMEVALUE(D5)+14/1440,1),"HH:MM") -> 03:59 | E12: =TEXT(MOD(TIMEVALUE(E5)+14/1440,1),"HH:MM") -> 04:44 | F12: =TEXT(MOD(TIMEVALUE(F5)+14/1440,1),"HH:MM") -> 04:59 | G12: =TEXT(MOD(TIMEVALUE(G5)+14/1440,1),"HH:MM") -> 05:14 | H12: =TEXT(MOD(TIMEVALUE(H5)+14/1440,1),"HH:MM") -> 05:29 | I12: =TEXT(MOD(TIMEVALUE(I5)+14/1440,1),"HH:MM") -> 05:44 | ... CP12: =TEXT(MOD(TIMEVALUE(CP5)+14/1440,1),"HH:MM") -> 00:13
A13: Rubén Darío | B13: =TEXT(MOD(TIMEVALUE(B5)+18/1440,1),"HH:MM") -> 01:18 | C13: =TEXT(MOD(TIMEVALUE(C5)+18/1440,1),"HH:MM") -> 02:48 | D13: =TEXT(MOD(TIMEVALUE(D5)+18/1440,1),"HH:MM") -> 04:03 | E13: =TEXT(MOD(TIMEVALUE(E5)+18/1440,1),"HH:MM") -> 04:48 | F13: =TEXT(MOD(TIMEVALUE(F5)+18/1440,1),"HH:MM") -> 05:03 | G13: =TEXT(MOD(TIMEVALUE(G5)+18/1440,1),"HH:MM") -> 05:18 | H13: =TEXT(MOD(TIMEVALUE(H5)+18/1440,1),"HH:MM") -> 05:33 | I13: =TEXT(MOD(TIMEVALUE(I5)+18/1440,1),"HH:MM") -> 05:48 | ... CP13: =TEXT(MOD(TIMEVALUE(CP5)+18/1440,1),"HH:MM") -> 00:17
A14: Jorge Newbery | B14: =TEXT(MOD(TIMEVALUE(B5)+20/1440,1),"HH:MM") -> 01:20 | C14: =TEXT(MOD(TIMEVALUE(C5)+20/1440,1),"HH:MM") -> 02:50 | D14: =TEXT(MOD(TIMEVALUE(D5)+20/1440,1),"HH:MM") -> 04:05 | E14: =TEXT(MOD(TIMEVALUE(E5)+20/1440,1),"HH:MM") -> 04:50 | F14: =TEXT(MOD(TIMEVALUE(F5)+20/1440,1),"HH:MM") -> 05:05 | G14: =TEXT(MOD(TIMEVALUE(G5)+20/1440,1),"HH:MM") -> 05:20 | H14: =TEXT(MOD(TIMEVALUE(H5)+20/1440,1),"HH:MM") -> 05:35 | I14: =TEXT(MOD(TIMEVALUE(I5)+20/1440,1),"HH:MM") -> 05:50 | ... CP14: =TEXT(MOD(TIMEVALUE(CP5)+20/1440,1),"HH:MM") -> 00:19
A15: Pedro Podestá | B15: =TEXT(MOD(TIMEVALUE(B5)+22/1440,1),"HH:MM") -> 01:22 | C15: =TEXT(MOD(TIMEVALUE(C5)+22/1440,1),"HH:MM") -> 02:52 | D15: =TEXT(MOD(TIMEVALUE(D5)+22/1440,1),"HH:MM") -> 04:07 | E15: =TEXT(MOD(TIMEVALUE(E5)+22/1440,1),"HH:MM") -> 04:52 | F15: =TEXT(MOD(TIMEVALUE(F5)+22/1440,1),"HH:MM") -> 05:07 | G15: =TEXT(MOD(TIMEVALUE(G5)+22/1440,1),"HH:MM") -> 05:22 | H15: =TEXT(MOD(TIMEVALUE(H5)+22/1440,1),"HH:MM") -> 05:37 | I15: =TEXT(MOD(TIMEVALUE(I5)+22/1440,1),"HH:MM") -> 05:52 | ... CP15: =TEXT(MOD(TIMEVALUE(CP5)+22/1440,1),"HH:MM") -> 00:21
A16: Martín Coronado | B16: =TEXT(MOD(TIMEVALUE(B5)+24/1440,1),"HH:MM") -> 01:24 | C16: =TEXT(MOD(TIMEVALUE(C5)+24/1440,1),"HH:MM") -> 02:54 | D16: =TEXT(MOD(TIMEVALUE(D5)+24/1440,1),"HH:MM") -> 04:09 | E16: =TEXT(MOD(TIMEVALUE(E5)+24/1440,1),"HH:MM") -> 04:54 | F16: =TEXT(MOD(TIMEVALUE(F5)+24/1440,1),"HH:MM") -> 05:09 | G16: =TEXT(MOD(TIMEVALUE(G5)+24/1440,1),"HH:MM") -> 05:24 | H16: =TEXT(MOD(TIMEVALUE(H5)+24/1440,1),"HH:MM") -> 05:39 | I16: =TEXT(MOD(TIMEVALUE(I5)+24/1440,1),"HH:MM") -> 05:54 | ... CP16: =TEXT(MOD(TIMEVALUE(CP5)+24/1440,1),"HH:MM") -> 00:23
A17: José M. Bosch | B17: =TEXT(MOD(TIMEVALUE(B5)+27/1440,1),"HH:MM") -> 01:27 | C17: =TEXT(MOD(TIMEVALUE(C5)+27/1440,1),"HH:MM") -> 02:57 | D17: =TEXT(MOD(TIMEVALUE(D5)+27/1440,1),"HH:MM") -> 04:12 | E17: =TEXT(MOD(TIMEVALUE(E5)+27/1440,1),"HH:MM") -> 04:57 | F17: =TEXT(MOD(TIMEVALUE(F5)+27/1440,1),"HH:MM") -> 05:12 | G17: =TEXT(MOD(TIMEVALUE(G5)+27/1440,1),"HH:MM") -> 05:27 | H17: =TEXT(MOD(TIMEVALUE(H5)+27/1440,1),"HH:MM") -> 05:42 | I17: =TEXT(MOD(TIMEVALUE(I5)+27/1440,1),"HH:MM") -> 05:57 | ... CP17: =TEXT(MOD(TIMEVALUE(CP5)+27/1440,1),"HH:MM") -> 00:26
A18: Tropezón | B18: =TEXT(MOD(TIMEVALUE(B5)+29/1440,1),"HH:MM") -> 01:29 | C18: =TEXT(MOD(TIMEVALUE(C5)+29/1440,1),"HH:MM") -> 02:59 | D18: =TEXT(MOD(TIMEVALUE(D5)+29/1440,1),"HH:MM") -> 04:14 | E18: =TEXT(MOD(TIMEVALUE(E5)+29/1440,1),"HH:MM") -> 04:59 | F18: =TEXT(MOD(TIMEVALUE(F5)+29/1440,1),"HH:MM") -> 05:14 | G18: =TEXT(MOD(TIMEVALUE(G5)+29/1440,1),"HH:MM") -> 05:29 | H18: =TEXT(MOD(TIMEVALUE(H5)+29/1440,1),"HH:MM") -> 05:44 | I18: =TEXT(MOD(TIMEVALUE(I5)+29/1440,1),"HH:MM") -> 05:59 | ... CP18: =TEXT(MOD(TIMEVALUE(CP5)+29/1440,1),"HH:MM") -> 00:28
A19: Lourdes | B19: =TEXT(MOD(TIMEVALUE(B5)+31/1440,1),"HH:MM") -> 01:31 | C19: =TEXT(MOD(TIMEVALUE(C5)+31/1440,1),"HH:MM") -> 03:01 | D19: =TEXT(MOD(TIMEVALUE(D5)+31/1440,1),"HH:MM") -> 04:16 | E19: =TEXT(MOD(TIMEVALUE(E5)+31/1440,1),"HH:MM") -> 05:01 | F19: =TEXT(MOD(TIMEVALUE(F5)+31/1440,1),"HH:MM") -> 05:16 | G19: =TEXT(MOD(TIMEVALUE(G5)+31/1440,1),"HH:MM") -> 05:31 | H19: =TEXT(MOD(TIMEVALUE(H5)+31/1440,1),"HH:MM") -> 05:46 | I19: =TEXT(MOD(TIMEVALUE(I5)+31/1440,1),"HH:MM") -> 06:01 | ... CP19: =TEXT(MOD(TIMEVALUE(CP5)+31/1440,1),"HH:MM") -> 00:30
A20: Fernández Moreno | B20: =TEXT(MOD(TIMEVALUE(B5)+33/1440,1),"HH:MM") -> 01:33 | C20: =TEXT(MOD(TIMEVALUE(C5)+33/1440,1),"HH:MM") -> 03:03 | D20: =TEXT(MOD(TIMEVALUE(D5)+33/1440,1),"HH:MM") -> 04:18 | E20: =TEXT(MOD(TIMEVALUE(E5)+33/1440,1),"HH:MM") -> 05:03 | F20: =TEXT(MOD(TIMEVALUE(F5)+33/1440,1),"HH:MM") -> 05:18 | G20: =TEXT(MOD(TIMEVALUE(G5)+33/1440,1),"HH:MM") -> 05:33 | H20: =TEXT(MOD(TIMEVALUE(H5)+33/1440,1),"HH:MM") -> 05:48 | I20: =TEXT(MOD(TIMEVALUE(I5)+33/1440,1),"HH:MM") -> 06:03 | ... CP20: =TEXT(MOD(TIMEVALUE(CP5)+33/1440,1),"HH:MM") -> 00:32
A21: Cnel. Fco. Lynch | B21: =TEXT(MOD(TIMEVALUE(B5)+35/1440,1),"HH:MM") -> 01:35 | C21: =TEXT(MOD(TIMEVALUE(C5)+35/1440,1),"HH:MM") -> 03:05 | D21: =TEXT(MOD(TIMEVALUE(D5)+35/1440,1),"HH:MM") -> 04:20 | E21: =TEXT(MOD(TIMEVALUE(E5)+35/1440,1),"HH:MM") -> 05:05 | F21: =TEXT(MOD(TIMEVALUE(F5)+35/1440,1),"HH:MM") -> 05:20 | G21: =TEXT(MOD(TIMEVALUE(G5)+35/1440,1),"HH:MM") -> 05:35 | H21: =TEXT(MOD(TIMEVALUE(H5)+35/1440,1),"HH:MM") -> 05:50 | I21: =TEXT(MOD(TIMEVALUE(I5)+35/1440,1),"HH:MM") -> 06:05 | ... CP21: =TEXT(MOD(TIMEVALUE(CP5)+35/1440,1),"HH:MM") -> 00:34
A22: Antonio Devoto | B22: =TEXT(MOD(TIMEVALUE(B5)+37/1440,1),"HH:MM") -> 01:37 | C22: =TEXT(MOD(TIMEVALUE(C5)+37/1440,1),"HH:MM") -> 03:07 | D22: =TEXT(MOD(TIMEVALUE(D5)+37/1440,1),"HH:MM") -> 04:22 | E22: =TEXT(MOD(TIMEVALUE(E5)+37/1440,1),"HH:MM") -> 05:07 | F22: =TEXT(MOD(TIMEVALUE(F5)+37/1440,1),"HH:MM") -> 05:22 | G22: =TEXT(MOD(TIMEVALUE(G5)+37/1440,1),"HH:MM") -> 05:37 | H22: =TEXT(MOD(TIMEVALUE(H5)+37/1440,1),"HH:MM") -> 05:52 | I22: =TEXT(MOD(TIMEVALUE(I5)+37/1440,1),"HH:MM") -> 06:07 | ... CP22: =TEXT(MOD(TIMEVALUE(CP5)+37/1440,1),"HH:MM") -> 00:36
A23: El Libertador | B23: =TEXT(MOD(TIMEVALUE(B5)+38/1440,1),"HH:MM") -> 01:38 | C23: =TEXT(MOD(TIMEVALUE(C5)+38/1440,1),"HH:MM") -> 03:08 | D23: =TEXT(MOD(TIMEVALUE(D5)+38/1440,1),"HH:MM") -> 04:23 | E23: =TEXT(MOD(TIMEVALUE(E5)+38/1440,1),"HH:MM") -> 05:08 | F23: =TEXT(MOD(TIMEVALUE(F5)+38/1440,1),"HH:MM") -> 05:23 | G23: =TEXT(MOD(TIMEVALUE(G5)+38/1440,1),"HH:MM") -> 05:38 | H23: =TEXT(MOD(TIMEVALUE(H5)+38/1440,1),"HH:MM") -> 05:53 | I23: =TEXT(MOD(TIMEVALUE(I5)+38/1440,1),"HH:MM") -> 06:08 | ... CP23: =TEXT(MOD(TIMEVALUE(CP5)+38/1440,1),"HH:MM") -> 00:37
A24: Dr. Fco. Beiró | B24: =TEXT(MOD(TIMEVALUE(B5)+39/1440,1),"HH:MM") -> 01:39 | C24: =TEXT(MOD(TIMEVALUE(C5)+39/1440,1),"HH:MM") -> 03:09 | D24: =TEXT(MOD(TIMEVALUE(D5)+39/1440,1),"HH:MM") -> 04:24 | E24: =TEXT(MOD(TIMEVALUE(E5)+39/1440,1),"HH:MM") -> 05:09 | F24: =TEXT(MOD(TIMEVALUE(F5)+39/1440,1),"HH:MM") -> 05:24 | G24: =TEXT(MOD(TIMEVALUE(G5)+39/1440,1),"HH:MM") -> 05:39 | H24: =TEXT(MOD(TIMEVALUE(H5)+39/1440,1),"HH:MM") -> 05:54 | I24: =TEXT(MOD(TIMEVALUE(I5)+39/1440,1),"HH:MM") -> 06:09 | ... CP24: =TEXT(MOD(TIMEVALUE(CP5)+39/1440,1),"HH:MM") -> 00:38
A25: Pedro N. Arata | B25: =TEXT(MOD(TIMEVALUE(B5)+42/1440,1),"HH:MM") -> 01:42 | C25: =TEXT(MOD(TIMEVALUE(C5)+42/1440,1),"HH:MM") -> 03:12 | D25: =TEXT(MOD(TIMEVALUE(D5)+42/1440,1),"HH:MM") -> 04:27 | E25: =TEXT(MOD(TIMEVALUE(E5)+42/1440,1),"HH:MM") -> 05:12 | F25: =TEXT(MOD(TIMEVALUE(F5)+42/1440,1),"HH:MM") -> 05:27 | G25: =TEXT(MOD(TIMEVALUE(G5)+42/1440,1),"HH:MM") -> 05:42 | H25: =TEXT(MOD(TIMEVALUE(H5)+42/1440,1),"HH:MM") -> 05:57 | I25: =TEXT(MOD(TIMEVALUE(I5)+42/1440,1),"HH:MM") -> 06:12 | ... CP25: =TEXT(MOD(TIMEVALUE(CP5)+42/1440,1),"HH:MM") -> 00:41
A26: José Artigas | B26: =TEXT(MOD(TIMEVALUE(B5)+44/1440,1),"HH:MM") -> 01:44 | C26: =TEXT(MOD(TIMEVALUE(C5)+44/1440,1),"HH:MM") -> 03:14 | D26: =TEXT(MOD(TIMEVALUE(D5)+44/1440,1),"HH:MM") -> 04:29 | E26: =TEXT(MOD(TIMEVALUE(E5)+44/1440,1),"HH:MM") -> 05:14 | F26: =TEXT(MOD(TIMEVALUE(F5)+44/1440,1),"HH:MM") -> 05:29 | G26: =TEXT(MOD(TIMEVALUE(G5)+44/1440,1),"HH:MM") -> 05:44 | H26: =TEXT(MOD(TIMEVALUE(H5)+44/1440,1),"HH:MM") -> 05:59 | I26: =TEXT(MOD(TIMEVALUE(I5)+44/1440,1),"HH:MM") -> 06:14 | ... CP26: =TEXT(MOD(TIMEVALUE(CP5)+44/1440,1),"HH:MM") -> 00:43
A27: Federico Lacroze | B27: =TEXT(MOD(TIMEVALUE(B5)+49/1440,1),"HH:MM") -> 01:49 | C27: =TEXT(MOD(TIMEVALUE(C5)+49/1440,1),"HH:MM") -> 03:19 | D27: =TEXT(MOD(TIMEVALUE(D5)+49/1440,1),"HH:MM") -> 04:34 | E27: =TEXT(MOD(TIMEVALUE(E5)+49/1440,1),"HH:MM") -> 05:19 | F27: =TEXT(MOD(TIMEVALUE(F5)+49/1440,1),"HH:MM") -> 05:34 | G27: =TEXT(MOD(TIMEVALUE(G5)+49/1440,1),"HH:MM") -> 05:49 | H27: =TEXT(MOD(TIMEVALUE(H5)+49/1440,1),"HH:MM") -> 06:04 | I27: =TEXT(MOD(TIMEVALUE(I5)+49/1440,1),"HH:MM") -> 06:19 | ... CP27: =TEXT(MOD(TIMEVALUE(CP5)+49/1440,1),"HH:MM") -> 00:48
A29: Fuente: Horario Mural Invierno 2026, Metrovías — metrovias.com.ar | Modificar la hora de salida en la fila de la estación de origen para recalcular todo el recorrido.

Sheet LM_Sabado
A1: Tren Urquiza — Sábados → Lacroze
A2: Salida desde General Lemos | Horario Mural Invierno 2026 — Metrovías
A4: Estación | B4: {=INDEX(INPUT!$C:$C, 102+COLUMN()-2)} -> 01:00 | C4: {=INDEX(INPUT!$C:$C, 102+COLUMN()-2)} -> 02:30 | D4: {=INDEX(INPUT!$C:$C, 102+COLUMN()-2)} -> 03:45 | E4: {=INDEX(INPUT!$C:$C, 102+COLUMN()-2)} -> 04:30 | F4: {=INDEX(INPUT!$C:$C, 102+COLUMN()-2)} -> 05:00 | G4: {=INDEX(INPUT!$C:$C, 102+COLUMN()-2)} -> 05:30 | H4: {=INDEX(INPUT!$C:$C, 102+COLUMN()-2)} -> 05:52 | I4: {=INDEX(INPUT!$C:$C, 102+COLUMN()-2)} -> 06:12 | ... BM4: {=INDEX(INPUT!$C:$C, 102+COLUMN()-2)} -> 23:48
A5: General Lemos | B5: =B4 -> 01:00 | C5: =C4 -> 02:30 | D5: =D4 -> 03:45 | E5: =E4 -> 04:30 | F5: =F4 -> 05:00 | G5: =G4 -> 05:30 | H5: =H4 -> 05:52 | I5: =I4 -> 06:12 | ... BM5: =BM4 -> 23:48
A6: Sargento Cabral | B6: =TEXT(MOD(TIMEVALUE(B5)+2/1440,1),"HH:MM") -> 01:02 | C6: =TEXT(MOD(TIMEVALUE(C5)+2/1440,1),"HH:MM") -> 02:32 | D6: =TEXT(MOD(TIMEVALUE(D5)+2/1440,1),"HH:MM") -> 03:47 | E6: =TEXT(MOD(TIMEVALUE(E5)+2/1440,1),"HH:MM") -> 04:32 | F6: =TEXT(MOD(TIMEVALUE(F5)+2/1440,1),"HH:MM") -> 05:02 | G6: =TEXT(MOD(TIMEVALUE(G5)+2/1440,1),"HH:MM") -> 05:32 | H6: =TEXT(MOD(TIMEVALUE(H5)+2/1440,1),"HH:MM") -> 05:54 | I6: =TEXT(MOD(TIMEVALUE(I5)+2/1440,1),"HH:MM") -> 06:14 | ... BM6: =TEXT(MOD(TIMEVALUE(BM5)+2/1440,1),"HH:MM") -> 23:50
A7: Campo de Mayo | B7: =TEXT(MOD(TIMEVALUE(B5)+4/1440,1),"HH:MM") -> 01:04 | C7: =TEXT(MOD(TIMEVALUE(C5)+4/1440,1),"HH:MM") -> 02:34 | D7: =TEXT(MOD(TIMEVALUE(D5)+4/1440,1),"HH:MM") -> 03:49 | E7: =TEXT(MOD(TIMEVALUE(E5)+4/1440,1),"HH:MM") -> 04:34 | F7: =TEXT(MOD(TIMEVALUE(F5)+4/1440,1),"HH:MM") -> 05:04 | G7: =TEXT(MOD(TIMEVALUE(G5)+4/1440,1),"HH:MM") -> 05:34 | H7: =TEXT(MOD(TIMEVALUE(H5)+4/1440,1),"HH:MM") -> 05:56 | I7: =TEXT(MOD(TIMEVALUE(I5)+4/1440,1),"HH:MM") -> 06:16 | ... BM7: =TEXT(MOD(TIMEVALUE(BM5)+4/1440,1),"HH:MM") -> 23:52
A8: Teniente Agneta | B8: =TEXT(MOD(TIMEVALUE(B5)+5/1440,1),"HH:MM") -> 01:05 | C8: =TEXT(MOD(TIMEVALUE(C5)+5/1440,1),"HH:MM") -> 02:35 | D8: =TEXT(MOD(TIMEVALUE(D5)+5/1440,1),"HH:MM") -> 03:50 | E8: =TEXT(MOD(TIMEVALUE(E5)+5/1440,1),"HH:MM") -> 04:35 | F8: =TEXT(MOD(TIMEVALUE(F5)+5/1440,1),"HH:MM") -> 05:05 | G8: =TEXT(MOD(TIMEVALUE(G5)+5/1440,1),"HH:MM") -> 05:35 | H8: =TEXT(MOD(TIMEVALUE(H5)+5/1440,1),"HH:MM") -> 05:57 | I8: =TEXT(MOD(TIMEVALUE(I5)+5/1440,1),"HH:MM") -> 06:17 | ... BM8: =TEXT(MOD(TIMEVALUE(BM5)+5/1440,1),"HH:MM") -> 23:53
A9: Capitán Lozano | B9: =TEXT(MOD(TIMEVALUE(B5)+7/1440,1),"HH:MM") -> 01:07 | C9: =TEXT(MOD(TIMEVALUE(C5)+7/1440,1),"HH:MM") -> 02:37 | D9: =TEXT(MOD(TIMEVALUE(D5)+7/1440,1),"HH:MM") -> 03:52 | E9: =TEXT(MOD(TIMEVALUE(E5)+7/1440,1),"HH:MM") -> 04:37 | F9: =TEXT(MOD(TIMEVALUE(F5)+7/1440,1),"HH:MM") -> 05:07 | G9: =TEXT(MOD(TIMEVALUE(G5)+7/1440,1),"HH:MM") -> 05:37 | H9: =TEXT(MOD(TIMEVALUE(H5)+7/1440,1),"HH:MM") -> 05:59 | I9: =TEXT(MOD(TIMEVALUE(I5)+7/1440,1),"HH:MM") -> 06:19 | ... BM9: =TEXT(MOD(TIMEVALUE(BM5)+7/1440,1),"HH:MM") -> 23:55
A10: Sgto. Barruffaldi | B10: =TEXT(MOD(TIMEVALUE(B5)+9/1440,1),"HH:MM") -> 01:09 | C10: =TEXT(MOD(TIMEVALUE(C5)+9/1440,1),"HH:MM") -> 02:39 | D10: =TEXT(MOD(TIMEVALUE(D5)+9/1440,1),"HH:MM") -> 03:54 | E10: =TEXT(MOD(TIMEVALUE(E5)+9/1440,1),"HH:MM") -> 04:39 | F10: =TEXT(MOD(TIMEVALUE(F5)+9/1440,1),"HH:MM") -> 05:09 | G10: =TEXT(MOD(TIMEVALUE(G5)+9/1440,1),"HH:MM") -> 05:39 | H10: =TEXT(MOD(TIMEVALUE(H5)+9/1440,1),"HH:MM") -> 06:01 | I10: =TEXT(MOD(TIMEVALUE(I5)+9/1440,1),"HH:MM") -> 06:21 | ... BM10: =TEXT(MOD(TIMEVALUE(BM5)+9/1440,1),"HH:MM") -> 23:57
A11: Juan E. de la Salle | B11: =TEXT(MOD(TIMEVALUE(B5)+12/1440,1),"HH:MM") -> 01:12 | C11: =TEXT(MOD(TIMEVALUE(C5)+12/1440,1),"HH:MM") -> 02:42 | D11: =TEXT(MOD(TIMEVALUE(D5)+12/1440,1),"HH:MM") -> 03:57 | E11: =TEXT(MOD(TIMEVALUE(E5)+12/1440,1),"HH:MM") -> 04:42 | F11: =TEXT(MOD(TIMEVALUE(F5)+12/1440,1),"HH:MM") -> 05:12 | G11: =TEXT(MOD(TIMEVALUE(G5)+12/1440,1),"HH:MM") -> 05:42 | H11: =TEXT(MOD(TIMEVALUE(H5)+12/1440,1),"HH:MM") -> 06:04 | I11: =TEXT(MOD(TIMEVALUE(I5)+12/1440,1),"HH:MM") -> 06:24 | ... BM11: =TEXT(MOD(TIMEVALUE(BM5)+12/1440,1),"HH:MM") -> 00:00
A12: Ejército de los Andes | B12: =TEXT(MOD(TIMEVALUE(B5)+14/1440,1),"HH:MM") -> 01:14 | C12: =TEXT(MOD(TIMEVALUE(C5)+14/1440,1),"HH:MM") -> 02:44 | D12: =TEXT(MOD(TIMEVALUE(D5)+14/1440,1),"HH:MM") -> 03:59 | E12: =TEXT(MOD(TIMEVALUE(E5)+14/1440,1),"HH:MM") -> 04:44 | F12: =TEXT(MOD(TIMEVALUE(F5)+14/1440,1),"HH:MM") -> 05:14 | G12: =TEXT(MOD(TIMEVALUE(G5)+14/1440,1),"HH:MM") -> 05:44 | H12: =TEXT(MOD(TIMEVALUE(H5)+14/1440,1),"HH:MM") -> 06:06 | I12: =TEXT(MOD(TIMEVALUE(I5)+14/1440,1),"HH:MM") -> 06:26 | ... BM12: =TEXT(MOD(TIMEVALUE(BM5)+14/1440,1),"HH:MM") -> 00:02
A13: Rubén Darío | B13: =TEXT(MOD(TIMEVALUE(B5)+18/1440,1),"HH:MM") -> 01:18 | C13: =TEXT(MOD(TIMEVALUE(C5)+18/1440,1),"HH:MM") -> 02:48 | D13: =TEXT(MOD(TIMEVALUE(D5)+18/1440,1),"HH:MM") -> 04:03 | E13: =TEXT(MOD(TIMEVALUE(E5)+18/1440,1),"HH:MM") -> 04:48 | F13: =TEXT(MOD(TIMEVALUE(F5)+18/1440,1),"HH:MM") -> 05:18 | G13: =TEXT(MOD(TIMEVALUE(G5)+18/1440,1),"HH:MM") -> 05:48 | H13: =TEXT(MOD(TIMEVALUE(H5)+18/1440,1),"HH:MM") -> 06:10 | I13: =TEXT(MOD(TIMEVALUE(I5)+18/1440,1),"HH:MM") -> 06:30 | ... BM13: =TEXT(MOD(TIMEVALUE(BM5)+18/1440,1),"HH:MM") -> 00:06
A14: Jorge Newbery | B14: =TEXT(MOD(TIMEVALUE(B5)+20/1440,1),"HH:MM") -> 01:20 | C14: =TEXT(MOD(TIMEVALUE(C5)+20/1440,1),"HH:MM") -> 02:50 | D14: =TEXT(MOD(TIMEVALUE(D5)+20/1440,1),"HH:MM") -> 04:05 | E14: =TEXT(MOD(TIMEVALUE(E5)+20/1440,1),"HH:MM") -> 04:50 | F14: =TEXT(MOD(TIMEVALUE(F5)+20/1440,1),"HH:MM") -> 05:20 | G14: =TEXT(MOD(TIMEVALUE(G5)+20/1440,1),"HH:MM") -> 05:50 | H14: =TEXT(MOD(TIMEVALUE(H5)+20/1440,1),"HH:MM") -> 06:12 | I14: =TEXT(MOD(TIMEVALUE(I5)+20/1440,1),"HH:MM") -> 06:32 | ... BM14: =TEXT(MOD(TIMEVALUE(BM5)+20/1440,1),"HH:MM") -> 00:08
A15: Pedro Podestá | B15: =TEXT(MOD(TIMEVALUE(B5)+22/1440,1),"HH:MM") -> 01:22 | C15: =TEXT(MOD(TIMEVALUE(C5)+22/1440,1),"HH:MM") -> 02:52 | D15: =TEXT(MOD(TIMEVALUE(D5)+22/1440,1),"HH:MM") -> 04:07 | E15: =TEXT(MOD(TIMEVALUE(E5)+22/1440,1),"HH:MM") -> 04:52 | F15: =TEXT(MOD(TIMEVALUE(F5)+22/1440,1),"HH:MM") -> 05:22 | G15: =TEXT(MOD(TIMEVALUE(G5)+22/1440,1),"HH:MM") -> 05:52 | H15: =TEXT(MOD(TIMEVALUE(H5)+22/1440,1),"HH:MM") -> 06:14 | I15: =TEXT(MOD(TIMEVALUE(I5)+22/1440,1),"HH:MM") -> 06:34 | ... BM15: =TEXT(MOD(TIMEVALUE(BM5)+22/1440,1),"HH:MM") -> 00:10
A16: Martín Coronado | B16: =TEXT(MOD(TIMEVALUE(B5)+24/1440,1),"HH:MM") -> 01:24 | C16: =TEXT(MOD(TIMEVALUE(C5)+24/1440,1),"HH:MM") -> 02:54 | D16: =TEXT(MOD(TIMEVALUE(D5)+24/1440,1),"HH:MM") -> 04:09 | E16: =TEXT(MOD(TIMEVALUE(E5)+24/1440,1),"HH:MM") -> 04:54 | F16: =TEXT(MOD(TIMEVALUE(F5)+24/1440,1),"HH:MM") -> 05:24 | G16: =TEXT(MOD(TIMEVALUE(G5)+24/1440,1),"HH:MM") -> 05:54 | H16: =TEXT(MOD(TIMEVALUE(H5)+24/1440,1),"HH:MM") -> 06:16 | I16: =TEXT(MOD(TIMEVALUE(I5)+24/1440,1),"HH:MM") -> 06:36 | ... BM16: =TEXT(MOD(TIMEVALUE(BM5)+24/1440,1),"HH:MM") -> 00:12
A17: José M. Bosch | B17: =TEXT(MOD(TIMEVALUE(B5)+27/1440,1),"HH:MM") -> 01:27 | C17: =TEXT(MOD(TIMEVALUE(C5)+27/1440,1),"HH:MM") -> 02:57 | D17: =TEXT(MOD(TIMEVALUE(D5)+27/1440,1),"HH:MM") -> 04:12 | E17: =TEXT(MOD(TIMEVALUE(E5)+27/1440,1),"HH:MM") -> 04:57 | F17: =TEXT(MOD(TIMEVALUE(F5)+27/1440,1),"HH:MM") -> 05:27 | G17: =TEXT(MOD(TIMEVALUE(G5)+27/1440,1),"HH:MM") -> 05:57 | H17: =TEXT(MOD(TIMEVALUE(H5)+27/1440,1),"HH:MM") -> 06:19 | I17: =TEXT(MOD(TIMEVALUE(I5)+27/1440,1),"HH:MM") -> 06:39 | ... BM17: =TEXT(MOD(TIMEVALUE(BM5)+27/1440,1),"HH:MM") -> 00:15
A18: Tropezón | B18: =TEXT(MOD(TIMEVALUE(B5)+29/1440,1),"HH:MM") -> 01:29 | C18: =TEXT(MOD(TIMEVALUE(C5)+29/1440,1),"HH:MM") -> 02:59 | D18: =TEXT(MOD(TIMEVALUE(D5)+29/1440,1),"HH:MM") -> 04:14 | E18: =TEXT(MOD(TIMEVALUE(E5)+29/1440,1),"HH:MM") -> 04:59 | F18: =TEXT(MOD(TIMEVALUE(F5)+29/1440,1),"HH:MM") -> 05:29 | G18: =TEXT(MOD(TIMEVALUE(G5)+29/1440,1),"HH:MM") -> 05:59 | H18: =TEXT(MOD(TIMEVALUE(H5)+29/1440,1),"HH:MM") -> 06:21 | I18: =TEXT(MOD(TIMEVALUE(I5)+29/1440,1),"HH:MM") -> 06:41 | ... BM18: =TEXT(MOD(TIMEVALUE(BM5)+29/1440,1),"HH:MM") -> 00:17
A19: Lourdes | B19: =TEXT(MOD(TIMEVALUE(B5)+31/1440,1),"HH:MM") -> 01:31 | C19: =TEXT(MOD(TIMEVALUE(C5)+31/1440,1),"HH:MM") -> 03:01 | D19: =TEXT(MOD(TIMEVALUE(D5)+31/1440,1),"HH:MM") -> 04:16 | E19: =TEXT(MOD(TIMEVALUE(E5)+31/1440,1),"HH:MM") -> 05:01 | F19: =TEXT(MOD(TIMEVALUE(F5)+31/1440,1),"HH:MM") -> 05:31 | G19: =TEXT(MOD(TIMEVALUE(G5)+31/1440,1),"HH:MM") -> 06:01 | H19: =TEXT(MOD(TIMEVALUE(H5)+31/1440,1),"HH:MM") -> 06:23 | I19: =TEXT(MOD(TIMEVALUE(I5)+31/1440,1),"HH:MM") -> 06:43 | ... BM19: =TEXT(MOD(TIMEVALUE(BM5)+31/1440,1),"HH:MM") -> 00:19
A20: Fernández Moreno | B20: =TEXT(MOD(TIMEVALUE(B5)+33/1440,1),"HH:MM") -> 01:33 | C20: =TEXT(MOD(TIMEVALUE(C5)+33/1440,1),"HH:MM") -> 03:03 | D20: =TEXT(MOD(TIMEVALUE(D5)+33/1440,1),"HH:MM") -> 04:18 | E20: =TEXT(MOD(TIMEVALUE(E5)+33/1440,1),"HH:MM") -> 05:03 | F20: =TEXT(MOD(TIMEVALUE(F5)+33/1440,1),"HH:MM") -> 05:33 | G20: =TEXT(MOD(TIMEVALUE(G5)+33/1440,1),"HH:MM") -> 06:03 | H20: =TEXT(MOD(TIMEVALUE(H5)+33/1440,1),"HH:MM") -> 06:25 | I20: =TEXT(MOD(TIMEVALUE(I5)+33/1440,1),"HH:MM") -> 06:45 | ... BM20: =TEXT(MOD(TIMEVALUE(BM5)+33/1440,1),"HH:MM") -> 00:21
A21: Cnel. Fco. Lynch | B21: =TEXT(MOD(TIMEVALUE(B5)+35/1440,1),"HH:MM") -> 01:35 | C21: =TEXT(MOD(TIMEVALUE(C5)+35/1440,1),"HH:MM") -> 03:05 | D21: =TEXT(MOD(TIMEVALUE(D5)+35/1440,1),"HH:MM") -> 04:20 | E21: =TEXT(MOD(TIMEVALUE(E5)+35/1440,1),"HH:MM") -> 05:05 | F21: =TEXT(MOD(TIMEVALUE(F5)+35/1440,1),"HH:MM") -> 05:35 | G21: =TEXT(MOD(TIMEVALUE(G5)+35/1440,1),"HH:MM") -> 06:05 | H21: =TEXT(MOD(TIMEVALUE(H5)+35/1440,1),"HH:MM") -> 06:27 | I21: =TEXT(MOD(TIMEVALUE(I5)+35/1440,1),"HH:MM") -> 06:47 | ... BM21: =TEXT(MOD(TIMEVALUE(BM5)+35/1440,1),"HH:MM") -> 00:23
A22: Antonio Devoto | B22: =TEXT(MOD(TIMEVALUE(B5)+37/1440,1),"HH:MM") -> 01:37 | C22: =TEXT(MOD(TIMEVALUE(C5)+37/1440,1),"HH:MM") -> 03:07 | D22: =TEXT(MOD(TIMEVALUE(D5)+37/1440,1),"HH:MM") -> 04:22 | E22: =TEXT(MOD(TIMEVALUE(E5)+37/1440,1),"HH:MM") -> 05:07 | F22: =TEXT(MOD(TIMEVALUE(F5)+37/1440,1),"HH:MM") -> 05:37 | G22: =TEXT(MOD(TIMEVALUE(G5)+37/1440,1),"HH:MM") -> 06:07 | H22: =TEXT(MOD(TIMEVALUE(H5)+37/1440,1),"HH:MM") -> 06:29 | I22: =TEXT(MOD(TIMEVALUE(I5)+37/1440,1),"HH:MM") -> 06:49 | ... BM22: =TEXT(MOD(TIMEVALUE(BM5)+37/1440,1),"HH:MM") -> 00:25
A23: El Libertador | B23: =TEXT(MOD(TIMEVALUE(B5)+38/1440,1),"HH:MM") -> 01:38 | C23: =TEXT(MOD(TIMEVALUE(C5)+38/1440,1),"HH:MM") -> 03:08 | D23: =TEXT(MOD(TIMEVALUE(D5)+38/1440,1),"HH:MM") -> 04:23 | E23: =TEXT(MOD(TIMEVALUE(E5)+38/1440,1),"HH:MM") -> 05:08 | F23: =TEXT(MOD(TIMEVALUE(F5)+38/1440,1),"HH:MM") -> 05:38 | G23: =TEXT(MOD(TIMEVALUE(G5)+38/1440,1),"HH:MM") -> 06:08 | H23: =TEXT(MOD(TIMEVALUE(H5)+38/1440,1),"HH:MM") -> 06:30 | I23: =TEXT(MOD(TIMEVALUE(I5)+38/1440,1),"HH:MM") -> 06:50 | ... BM23: =TEXT(MOD(TIMEVALUE(BM5)+38/1440,1),"HH:MM") -> 00:26
A24: Dr. Fco. Beiró | B24: =TEXT(MOD(TIMEVALUE(B5)+39/1440,1),"HH:MM") -> 01:39 | C24: =TEXT(MOD(TIMEVALUE(C5)+39/1440,1),"HH:MM") -> 03:09 | D24: =TEXT(MOD(TIMEVALUE(D5)+39/1440,1),"HH:MM") -> 04:24 | E24: =TEXT(MOD(TIMEVALUE(E5)+39/1440,1),"HH:MM") -> 05:09 | F24: =TEXT(MOD(TIMEVALUE(F5)+39/1440,1),"HH:MM") -> 05:39 | G24: =TEXT(MOD(TIMEVALUE(G5)+39/1440,1),"HH:MM") -> 06:09 | H24: =TEXT(MOD(TIMEVALUE(H5)+39/1440,1),"HH:MM") -> 06:31 | I24: =TEXT(MOD(TIMEVALUE(I5)+39/1440,1),"HH:MM") -> 06:51 | ... BM24: =TEXT(MOD(TIMEVALUE(BM5)+39/1440,1),"HH:MM") -> 00:27
A25: Pedro N. Arata | B25: =TEXT(MOD(TIMEVALUE(B5)+42/1440,1),"HH:MM") -> 01:42 | C25: =TEXT(MOD(TIMEVALUE(C5)+42/1440,1),"HH:MM") -> 03:12 | D25: =TEXT(MOD(TIMEVALUE(D5)+42/1440,1),"HH:MM") -> 04:27 | E25: =TEXT(MOD(TIMEVALUE(E5)+42/1440,1),"HH:MM") -> 05:12 | F25: =TEXT(MOD(TIMEVALUE(F5)+42/1440,1),"HH:MM") -> 05:42 | G25: =TEXT(MOD(TIMEVALUE(G5)+42/1440,1),"HH:MM") -> 06:12 | H25: =TEXT(MOD(TIMEVALUE(H5)+42/1440,1),"HH:MM") -> 06:34 | I25: =TEXT(MOD(TIMEVALUE(I5)+42/1440,1),"HH:MM") -> 06:54 | ... BM25: =TEXT(MOD(TIMEVALUE(BM5)+42/1440,1),"HH:MM") -> 00:30
A26: José Artigas | B26: =TEXT(MOD(TIMEVALUE(B5)+44/1440,1),"HH:MM") -> 01:44 | C26: =TEXT(MOD(TIMEVALUE(C5)+44/1440,1),"HH:MM") -> 03:14 | D26: =TEXT(MOD(TIMEVALUE(D5)+44/1440,1),"HH:MM") -> 04:29 | E26: =TEXT(MOD(TIMEVALUE(E5)+44/1440,1),"HH:MM") -> 05:14 | F26: =TEXT(MOD(TIMEVALUE(F5)+44/1440,1),"HH:MM") -> 05:44 | G26: =TEXT(MOD(TIMEVALUE(G5)+44/1440,1),"HH:MM") -> 06:14 | H26: =TEXT(MOD(TIMEVALUE(H5)+44/1440,1),"HH:MM") -> 06:36 | I26: =TEXT(MOD(TIMEVALUE(I5)+44/1440,1),"HH:MM") -> 06:56 | ... BM26: =TEXT(MOD(TIMEVALUE(BM5)+44/1440,1),"HH:MM") -> 00:32
A27: Federico Lacroze | B27: =TEXT(MOD(TIMEVALUE(B5)+49/1440,1),"HH:MM") -> 01:49 | C27: =TEXT(MOD(TIMEVALUE(C5)+49/1440,1),"HH:MM") -> 03:19 | D27: =TEXT(MOD(TIMEVALUE(D5)+49/1440,1),"HH:MM") -> 04:34 | E27: =TEXT(MOD(TIMEVALUE(E5)+49/1440,1),"HH:MM") -> 05:19 | F27: =TEXT(MOD(TIMEVALUE(F5)+49/1440,1),"HH:MM") -> 05:49 | G27: =TEXT(MOD(TIMEVALUE(G5)+49/1440,1),"HH:MM") -> 06:19 | H27: =TEXT(MOD(TIMEVALUE(H5)+49/1440,1),"HH:MM") -> 06:41 | I27: =TEXT(MOD(TIMEVALUE(I5)+49/1440,1),"HH:MM") -> 07:01 | ... BM27: =TEXT(MOD(TIMEVALUE(BM5)+49/1440,1),"HH:MM") -> 00:37
A29: Fuente: Horario Mural Invierno 2026, Metrovías — metrovias.com.ar | Modificar la hora de salida en la fila de la estación de origen para recalcular todo el recorrido.

Sheet LM_Domingo
A1: Tren Urquiza — Domingos → Lacroze
A2: Salida desde General Lemos | Horario Mural Invierno 2026 — Metrovías
A4: Estación | B4: {=INDEX(INPUT!$C:$C, 169+COLUMN()-2)} -> 00:01 | C4: {=INDEX(INPUT!$C:$C, 169+COLUMN()-2)} -> 03:12 | D4: {=INDEX(INPUT!$C:$C, 169+COLUMN()-2)} -> 04:15 | E4: {=INDEX(INPUT!$C:$C, 169+COLUMN()-2)} -> 05:30 | F4: {=INDEX(INPUT!$C:$C, 169+COLUMN()-2)} -> 06:20 | G4: {=INDEX(INPUT!$C:$C, 169+COLUMN()-2)} -> 06:55 | H4: {=INDEX(INPUT!$C:$C, 169+COLUMN()-2)} -> 07:25 | I4: {=INDEX(INPUT!$C:$C, 169+COLUMN()-2)} -> 07:55 | ... AN4: {=INDEX(INPUT!$C:$C, 169+COLUMN()-2)} -> 23:35
A5: General Lemos | B5: =B4 -> 00:01 | C5: =C4 -> 03:12 | D5: =D4 -> 04:15 | E5: =E4 -> 05:30 | F5: =F4 -> 06:20 | G5: =G4 -> 06:55 | H5: =H4 -> 07:25 | I5: =I4 -> 07:55 | ... AN5: =AN4 -> 23:35
A6: Sargento Cabral | B6: =TEXT(MOD(TIMEVALUE(B5)+2/1440,1),"HH:MM") -> 00:03 | C6: =TEXT(MOD(TIMEVALUE(C5)+2/1440,1),"HH:MM") -> 03:14 | D6: =TEXT(MOD(TIMEVALUE(D5)+2/1440,1),"HH:MM") -> 04:17 | E6: =TEXT(MOD(TIMEVALUE(E5)+2/1440,1),"HH:MM") -> 05:32 | F6: =TEXT(MOD(TIMEVALUE(F5)+2/1440,1),"HH:MM") -> 06:22 | G6: =TEXT(MOD(TIMEVALUE(G5)+2/1440,1),"HH:MM") -> 06:57 | H6: =TEXT(MOD(TIMEVALUE(H5)+2/1440,1),"HH:MM") -> 07:27 | I6: =TEXT(MOD(TIMEVALUE(I5)+2/1440,1),"HH:MM") -> 07:57 | ... AN6: =TEXT(MOD(TIMEVALUE(AN5)+2/1440,1),"HH:MM") -> 23:37
A7: Campo de Mayo | B7: =TEXT(MOD(TIMEVALUE(B5)+4/1440,1),"HH:MM") -> 00:05 | C7: =TEXT(MOD(TIMEVALUE(C5)+4/1440,1),"HH:MM") -> 03:16 | D7: =TEXT(MOD(TIMEVALUE(D5)+4/1440,1),"HH:MM") -> 04:19 | E7: =TEXT(MOD(TIMEVALUE(E5)+4/1440,1),"HH:MM") -> 05:34 | F7: =TEXT(MOD(TIMEVALUE(F5)+4/1440,1),"HH:MM") -> 06:24 | G7: =TEXT(MOD(TIMEVALUE(G5)+4/1440,1),"HH:MM") -> 06:59 | H7: =TEXT(MOD(TIMEVALUE(H5)+4/1440,1),"HH:MM") -> 07:29 | I7: =TEXT(MOD(TIMEVALUE(I5)+4/1440,1),"HH:MM") -> 07:59 | ... AN7: =TEXT(MOD(TIMEVALUE(AN5)+4/1440,1),"HH:MM") -> 23:39
A8: Teniente Agneta | B8: =TEXT(MOD(TIMEVALUE(B5)+5/1440,1),"HH:MM") -> 00:06 | C8: =TEXT(MOD(TIMEVALUE(C5)+5/1440,1),"HH:MM") -> 03:17 | D8: =TEXT(MOD(TIMEVALUE(D5)+5/1440,1),"HH:MM") -> 04:20 | E8: =TEXT(MOD(TIMEVALUE(E5)+5/1440,1),"HH:MM") -> 05:35 | F8: =TEXT(MOD(TIMEVALUE(F5)+5/1440,1),"HH:MM") -> 06:25 | G8: =TEXT(MOD(TIMEVALUE(G5)+5/1440,1),"HH:MM") -> 07:00 | H8: =TEXT(MOD(TIMEVALUE(H5)+5/1440,1),"HH:MM") -> 07:30 | I8: =TEXT(MOD(TIMEVALUE(I5)+5/1440,1),"HH:MM") -> 08:00 | ... AN8: =TEXT(MOD(TIMEVALUE(AN5)+5/1440,1),"HH:MM") -> 23:40
A9: Capitán Lozano | B9: =TEXT(MOD(TIMEVALUE(B5)+7/1440,1),"HH:MM") -> 00:08 | C9: =TEXT(MOD(TIMEVALUE(C5)+7/1440,1),"HH:MM") -> 03:19 | D9: =TEXT(MOD(TIMEVALUE(D5)+7/1440,1),"HH:MM") -> 04:22 | E9: =TEXT(MOD(TIMEVALUE(E5)+7/1440,1),"HH:MM") -> 05:37 | F9: =TEXT(MOD(TIMEVALUE(F5)+7/1440,1),"HH:MM") -> 06:27 | G9: =TEXT(MOD(TIMEVALUE(G5)+7/1440,1),"HH:MM") -> 07:02 | H9: =TEXT(MOD(TIMEVALUE(H5)+7/1440,1),"HH:MM") -> 07:32 | I9: =TEXT(MOD(TIMEVALUE(I5)+7/1440,1),"HH:MM") -> 08:02 | ... AN9: =TEXT(MOD(TIMEVALUE(AN5)+7/1440,1),"HH:MM") -> 23:42
A10: Sgto. Barruffaldi | B10: =TEXT(MOD(TIMEVALUE(B5)+9/1440,1),"HH:MM") -> 00:10 | C10: =TEXT(MOD(TIMEVALUE(C5)+9/1440,1),"HH:MM") -> 03:21 | D10: =TEXT(MOD(TIMEVALUE(D5)+9/1440,1),"HH:MM") -> 04:24 | E10: =TEXT(MOD(TIMEVALUE(E5)+9/1440,1),"HH:MM") -> 05:39 | F10: =TEXT(MOD(TIMEVALUE(F5)+9/1440,1),"HH:MM") -> 06:29 | G10: =TEXT(MOD(TIMEVALUE(G5)+9/1440,1),"HH:MM") -> 07:04 | H10: =TEXT(MOD(TIMEVALUE(H5)+9/1440,1),"HH:MM") -> 07:34 | I10: =TEXT(MOD(TIMEVALUE(I5)+9/1440,1),"HH:MM") -> 08:04 | ... AN10: =TEXT(MOD(TIMEVALUE(AN5)+9/1440,1),"HH:MM") -> 23:44
A11: Juan E. de la Salle | B11: =TEXT(MOD(TIMEVALUE(B5)+12/1440,1),"HH:MM") -> 00:13 | C11: =TEXT(MOD(TIMEVALUE(C5)+12/1440,1),"HH:MM") -> 03:24 | D11: =TEXT(MOD(TIMEVALUE(D5)+12/1440,1),"HH:MM") -> 04:27 | E11: =TEXT(MOD(TIMEVALUE(E5)+12/1440,1),"HH:MM") -> 05:42 | F11: =TEXT(MOD(TIMEVALUE(F5)+12/1440,1),"HH:MM") -> 06:32 | G11: =TEXT(MOD(TIMEVALUE(G5)+12/1440,1),"HH:MM") -> 07:07 | H11: =TEXT(MOD(TIMEVALUE(H5)+12/1440,1),"HH:MM") -> 07:37 | I11: =TEXT(MOD(TIMEVALUE(I5)+12/1440,1),"HH:MM") -> 08:07 | ... AN11: =TEXT(MOD(TIMEVALUE(AN5)+12/1440,1),"HH:MM") -> 23:47
A12: Ejército de los Andes | B12: =TEXT(MOD(TIMEVALUE(B5)+14/1440,1),"HH:MM") -> 00:15 | C12: =TEXT(MOD(TIMEVALUE(C5)+14/1440,1),"HH:MM") -> 03:26 | D12: =TEXT(MOD(TIMEVALUE(D5)+14/1440,1),"HH:MM") -> 04:29 | E12: =TEXT(MOD(TIMEVALUE(E5)+14/1440,1),"HH:MM") -> 05:44 | F12: =TEXT(MOD(TIMEVALUE(F5)+14/1440,1),"HH:MM") -> 06:34 | G12: =TEXT(MOD(TIMEVALUE(G5)+14/1440,1),"HH:MM") -> 07:09 | H12: =TEXT(MOD(TIMEVALUE(H5)+14/1440,1),"HH:MM") -> 07:39 | I12: =TEXT(MOD(TIMEVALUE(I5)+14/1440,1),"HH:MM") -> 08:09 | ... AN12: =TEXT(MOD(TIMEVALUE(AN5)+14/1440,1),"HH:MM") -> 23:49
A13: Rubén Darío | B13: =TEXT(MOD(TIMEVALUE(B5)+18/1440,1),"HH:MM") -> 00:19 | C13: =TEXT(MOD(TIMEVALUE(C5)+18/1440,1),"HH:MM") -> 03:30 | D13: =TEXT(MOD(TIMEVALUE(D5)+18/1440,1),"HH:MM") -> 04:33 | E13: =TEXT(MOD(TIMEVALUE(E5)+18/1440,1),"HH:MM") -> 05:48 | F13: =TEXT(MOD(TIMEVALUE(F5)+18/1440,1),"HH:MM") -> 06:38 | G13: =TEXT(MOD(TIMEVALUE(G5)+18/1440,1),"HH:MM") -> 07:13 | H13: =TEXT(MOD(TIMEVALUE(H5)+18/1440,1),"HH:MM") -> 07:43 | I13: =TEXT(MOD(TIMEVALUE(I5)+18/1440,1),"HH:MM") -> 08:13 | ... AN13: =TEXT(MOD(TIMEVALUE(AN5)+18/1440,1),"HH:MM") -> 23:53
A14: Jorge Newbery | B14: =TEXT(MOD(TIMEVALUE(B5)+20/1440,1),"HH:MM") -> 00:21 | C14: =TEXT(MOD(TIMEVALUE(C5)+20/1440,1),"HH:MM") -> 03:32 | D14: =TEXT(MOD(TIMEVALUE(D5)+20/1440,1),"HH:MM") -> 04:35 | E14: =TEXT(MOD(TIMEVALUE(E5)+20/1440,1),"HH:MM") -> 05:50 | F14: =TEXT(MOD(TIMEVALUE(F5)+20/1440,1),"HH:MM") -> 06:40 | G14: =TEXT(MOD(TIMEVALUE(G5)+20/1440,1),"HH:MM") -> 07:15 | H14: =TEXT(MOD(TIMEVALUE(H5)+20/1440,1),"HH:MM") -> 07:45 | I14: =TEXT(MOD(TIMEVALUE(I5)+20/1440,1),"HH:MM") -> 08:15 | ... AN14: =TEXT(MOD(TIMEVALUE(AN5)+20/1440,1),"HH:MM") -> 23:55
A15: Pedro Podestá | B15: =TEXT(MOD(TIMEVALUE(B5)+22/1440,1),"HH:MM") -> 00:23 | C15: =TEXT(MOD(TIMEVALUE(C5)+22/1440,1),"HH:MM") -> 03:34 | D15: =TEXT(MOD(TIMEVALUE(D5)+22/1440,1),"HH:MM") -> 04:37 | E15: =TEXT(MOD(TIMEVALUE(E5)+22/1440,1),"HH:MM") -> 05:52 | F15: =TEXT(MOD(TIMEVALUE(F5)+22/1440,1),"HH:MM") -> 06:42 | G15: =TEXT(MOD(TIMEVALUE(G5)+22/1440,1),"HH:MM") -> 07:17 | H15: =TEXT(MOD(TIMEVALUE(H5)+22/1440,1),"HH:MM") -> 07:47 | I15: =TEXT(MOD(TIMEVALUE(I5)+22/1440,1),"HH:MM") -> 08:17 | ... AN15: =TEXT(MOD(TIMEVALUE(AN5)+22/1440,1),"HH:MM") -> 23:57
A16: Martín Coronado | B16: =TEXT(MOD(TIMEVALUE(B5)+24/1440,1),"HH:MM") -> 00:25 | C16: =TEXT(MOD(TIMEVALUE(C5)+24/1440,1),"HH:MM") -> 03:36 | D16: =TEXT(MOD(TIMEVALUE(D5)+24/1440,1),"HH:MM") -> 04:39 | E16: =TEXT(MOD(TIMEVALUE(E5)+24/1440,1),"HH:MM") -> 05:54 | F16: =TEXT(MOD(TIMEVALUE(F5)+24/1440,1),"HH:MM") -> 06:44 | G16: =TEXT(MOD(TIMEVALUE(G5)+24/1440,1),"HH:MM") -> 07:19 | H16: =TEXT(MOD(TIMEVALUE(H5)+24/1440,1),"HH:MM") -> 07:49 | I16: =TEXT(MOD(TIMEVALUE(I5)+24/1440,1),"HH:MM") -> 08:19 | ... AN16: =TEXT(MOD(TIMEVALUE(AN5)+24/1440,1),"HH:MM") -> 23:59
A17: José M. Bosch | B17: =TEXT(MOD(TIMEVALUE(B5)+27/1440,1),"HH:MM") -> 00:28 | C17: =TEXT(MOD(TIMEVALUE(C5)+27/1440,1),"HH:MM") -> 03:39 | D17: =TEXT(MOD(TIMEVALUE(D5)+27/1440,1),"HH:MM") -> 04:42 | E17: =TEXT(MOD(TIMEVALUE(E5)+27/1440,1),"HH:MM") -> 05:57 | F17: =TEXT(MOD(TIMEVALUE(F5)+27/1440,1),"HH:MM") -> 06:47 | G17: =TEXT(MOD(TIMEVALUE(G5)+27/1440,1),"HH:MM") -> 07:22 | H17: =TEXT(MOD(TIMEVALUE(H5)+27/1440,1),"HH:MM") -> 07:52 | I17: =TEXT(MOD(TIMEVALUE(I5)+27/1440,1),"HH:MM") -> 08:22 | ... AN17: =TEXT(MOD(TIMEVALUE(AN5)+27/1440,1),"HH:MM") -> 00:02
A18: Tropezón | B18: =TEXT(MOD(TIMEVALUE(B5)+29/1440,1),"HH:MM") -> 00:30 | C18: =TEXT(MOD(TIMEVALUE(C5)+29/1440,1),"HH:MM") -> 03:41 | D18: =TEXT(MOD(TIMEVALUE(D5)+29/1440,1),"HH:MM") -> 04:44 | E18: =TEXT(MOD(TIMEVALUE(E5)+29/1440,1),"HH:MM") -> 05:59 | F18: =TEXT(MOD(TIMEVALUE(F5)+29/1440,1),"HH:MM") -> 06:49 | G18: =TEXT(MOD(TIMEVALUE(G5)+29/1440,1),"HH:MM") -> 07:24 | H18: =TEXT(MOD(TIMEVALUE(H5)+29/1440,1),"HH:MM") -> 07:54 | I18: =TEXT(MOD(TIMEVALUE(I5)+29/1440,1),"HH:MM") -> 08:24 | ... AN18: =TEXT(MOD(TIMEVALUE(AN5)+29/1440,1),"HH:MM") -> 00:04
A19: Lourdes | B19: =TEXT(MOD(TIMEVALUE(B5)+31/1440,1),"HH:MM") -> 00:32 | C19: =TEXT(MOD(TIMEVALUE(C5)+31/1440,1),"HH:MM") -> 03:43 | D19: =TEXT(MOD(TIMEVALUE(D5)+31/1440,1),"HH:MM") -> 04:46 | E19: =TEXT(MOD(TIMEVALUE(E5)+31/1440,1),"HH:MM") -> 06:01 | F19: =TEXT(MOD(TIMEVALUE(F5)+31/1440,1),"HH:MM") -> 06:51 | G19: =TEXT(MOD(TIMEVALUE(G5)+31/1440,1),"HH:MM") -> 07:26 | H19: =TEXT(MOD(TIMEVALUE(H5)+31/1440,1),"HH:MM") -> 07:56 | I19: =TEXT(MOD(TIMEVALUE(I5)+31/1440,1),"HH:MM") -> 08:26 | ... AN19: =TEXT(MOD(TIMEVALUE(AN5)+31/1440,1),"HH:MM") -> 00:06
A20: Fernández Moreno | B20: =TEXT(MOD(TIMEVALUE(B5)+33/1440,1),"HH:MM") -> 00:34 | C20: =TEXT(MOD(TIMEVALUE(C5)+33/1440,1),"HH:MM") -> 03:45 | D20: =TEXT(MOD(TIMEVALUE(D5)+33/1440,1),"HH:MM") -> 04:48 | E20: =TEXT(MOD(TIMEVALUE(E5)+33/1440,1),"HH:MM") -> 06:03 | F20: =TEXT(MOD(TIMEVALUE(F5)+33/1440,1),"HH:MM") -> 06:53 | G20: =TEXT(MOD(TIMEVALUE(G5)+33/1440,1),"HH:MM") -> 07:28 | H20: =TEXT(MOD(TIMEVALUE(H5)+33/1440,1),"HH:MM") -> 07:58 | I20: =TEXT(MOD(TIMEVALUE(I5)+33/1440,1),"HH:MM") -> 08:28 | ... AN20: =TEXT(MOD(TIMEVALUE(AN5)+33/1440,1),"HH:MM") -> 00:08
A21: Cnel. Fco. Lynch | B21: =TEXT(MOD(TIMEVALUE(B5)+35/1440,1),"HH:MM") -> 00:36 | C21: =TEXT(MOD(TIMEVALUE(C5)+35/1440,1),"HH:MM") -> 03:47 | D21: =TEXT(MOD(TIMEVALUE(D5)+35/1440,1),"HH:MM") -> 04:50 | E21: =TEXT(MOD(TIMEVALUE(E5)+35/1440,1),"HH:MM") -> 06:05 | F21: =TEXT(MOD(TIMEVALUE(F5)+35/1440,1),"HH:MM") -> 06:55 | G21: =TEXT(MOD(TIMEVALUE(G5)+35/1440,1),"HH:MM") -> 07:30 | H21: =TEXT(MOD(TIMEVALUE(H5)+35/1440,1),"HH:MM") -> 08:00 | I21: =TEXT(MOD(TIMEVALUE(I5)+35/1440,1),"HH:MM") -> 08:30 | ... AN21: =TEXT(MOD(TIMEVALUE(AN5)+35/1440,1),"HH:MM") -> 00:10
A22: Antonio Devoto | B22: =TEXT(MOD(TIMEVALUE(B5)+37/1440,1),"HH:MM") -> 00:38 | C22: =TEXT(MOD(TIMEVALUE(C5)+37/1440,1),"HH:MM") -> 03:49 | D22: =TEXT(MOD(TIMEVALUE(D5)+37/1440,1),"HH:MM") -> 04:52 | E22: =TEXT(MOD(TIMEVALUE(E5)+37/1440,1),"HH:MM") -> 06:07 | F22: =TEXT(MOD(TIMEVALUE(F5)+37/1440,1),"HH:MM") -> 06:57 | G22: =TEXT(MOD(TIMEVALUE(G5)+37/1440,1),"HH:MM") -> 07:32 | H22: =TEXT(MOD(TIMEVALUE(H5)+37/1440,1),"HH:MM") -> 08:02 | I22: =TEXT(MOD(TIMEVALUE(I5)+37/1440,1),"HH:MM") -> 08:32 | ... AN22: =TEXT(MOD(TIMEVALUE(AN5)+37/1440,1),"HH:MM") -> 00:12
A23: El Libertador | B23: =TEXT(MOD(TIMEVALUE(B5)+38/1440,1),"HH:MM") -> 00:39 | C23: =TEXT(MOD(TIMEVALUE(C5)+38/1440,1),"HH:MM") -> 03:50 | D23: =TEXT(MOD(TIMEVALUE(D5)+38/1440,1),"HH:MM") -> 04:53 | E23: =TEXT(MOD(TIMEVALUE(E5)+38/1440,1),"HH:MM") -> 06:08 | F23: =TEXT(MOD(TIMEVALUE(F5)+38/1440,1),"HH:MM") -> 06:58 | G23: =TEXT(MOD(TIMEVALUE(G5)+38/1440,1),"HH:MM") -> 07:33 | H23: =TEXT(MOD(TIMEVALUE(H5)+38/1440,1),"HH:MM") -> 08:03 | I23: =TEXT(MOD(TIMEVALUE(I5)+38/1440,1),"HH:MM") -> 08:33 | ... AN23: =TEXT(MOD(TIMEVALUE(AN5)+38/1440,1),"HH:MM") -> 00:13
A24: Dr. Fco. Beiró | B24: =TEXT(MOD(TIMEVALUE(B5)+39/1440,1),"HH:MM") -> 00:40 | C24: =TEXT(MOD(TIMEVALUE(C5)+39/1440,1),"HH:MM") -> 03:51 | D24: =TEXT(MOD(TIMEVALUE(D5)+39/1440,1),"HH:MM") -> 04:54 | E24: =TEXT(MOD(TIMEVALUE(E5)+39/1440,1),"HH:MM") -> 06:09 | F24: =TEXT(MOD(TIMEVALUE(F5)+39/1440,1),"HH:MM") -> 06:59 | G24: =TEXT(MOD(TIMEVALUE(G5)+39/1440,1),"HH:MM") -> 07:34 | H24: =TEXT(MOD(TIMEVALUE(H5)+39/1440,1),"HH:MM") -> 08:04 | I24: =TEXT(MOD(TIMEVALUE(I5)+39/1440,1),"HH:MM") -> 08:34 | ... AN24: =TEXT(MOD(TIMEVALUE(AN5)+39/1440,1),"HH:MM") -> 00:14
A25: Pedro N. Arata | B25: =TEXT(MOD(TIMEVALUE(B5)+42/1440,1),"HH:MM") -> 00:43 | C25: =TEXT(MOD(TIMEVALUE(C5)+42/1440,1),"HH:MM") -> 03:54 | D25: =TEXT(MOD(TIMEVALUE(D5)+42/1440,1),"HH:MM") -> 04:57 | E25: =TEXT(MOD(TIMEVALUE(E5)+42/1440,1),"HH:MM") -> 06:12 | F25: =TEXT(MOD(TIMEVALUE(F5)+42/1440,1),"HH:MM") -> 07:02 | G25: =TEXT(MOD(TIMEVALUE(G5)+42/1440,1),"HH:MM") -> 07:37 | H25: =TEXT(MOD(TIMEVALUE(H5)+42/1440,1),"HH:MM") -> 08:07 | I25: =TEXT(MOD(TIMEVALUE(I5)+42/1440,1),"HH:MM") -> 08:37 | ... AN25: =TEXT(MOD(TIMEVALUE(AN5)+42/1440,1),"HH:MM") -> 00:17
A26: José Artigas | B26: =TEXT(MOD(TIMEVALUE(B5)+44/1440,1),"HH:MM") -> 00:45 | C26: =TEXT(MOD(TIMEVALUE(C5)+44/1440,1),"HH:MM") -> 03:56 | D26: =TEXT(MOD(TIMEVALUE(D5)+44/1440,1),"HH:MM") -> 04:59 | E26: =TEXT(MOD(TIMEVALUE(E5)+44/1440,1),"HH:MM") -> 06:14 | F26: =TEXT(MOD(TIMEVALUE(F5)+44/1440,1),"HH:MM") -> 07:04 | G26: =TEXT(MOD(TIMEVALUE(G5)+44/1440,1),"HH:MM") -> 07:39 | H26: =TEXT(MOD(TIMEVALUE(H5)+44/1440,1),"HH:MM") -> 08:09 | I26: =TEXT(MOD(TIMEVALUE(I5)+44/1440,1),"HH:MM") -> 08:39 | ... AN26: =TEXT(MOD(TIMEVALUE(AN5)+44/1440,1),"HH:MM") -> 00:19
A27: Federico Lacroze | B27: =TEXT(MOD(TIMEVALUE(B5)+49/1440,1),"HH:MM") -> 00:50 | C27: =TEXT(MOD(TIMEVALUE(C5)+49/1440,1),"HH:MM") -> 04:01 | D27: =TEXT(MOD(TIMEVALUE(D5)+49/1440,1),"HH:MM") -> 05:04 | E27: =TEXT(MOD(TIMEVALUE(E5)+49/1440,1),"HH:MM") -> 06:19 | F27: =TEXT(MOD(TIMEVALUE(F5)+49/1440,1),"HH:MM") -> 07:09 | G27: =TEXT(MOD(TIMEVALUE(G5)+49/1440,1),"HH:MM") -> 07:44 | H27: =TEXT(MOD(TIMEVALUE(H5)+49/1440,1),"HH:MM") -> 08:14 | I27: =TEXT(MOD(TIMEVALUE(I5)+49/1440,1),"HH:MM") -> 08:44 | ... AN27: =TEXT(MOD(TIMEVALUE(AN5)+49/1440,1),"HH:MM") -> 00:24
A29: Fuente: Horario Mural Invierno 2026, Metrovías — metrovias.com.ar | Modificar la hora de salida en la fila de la estación de origen para recalcular todo el recorrido.

Sheet LM_Feriado
A1: Tren Urquiza — Feriados → Lacroze
A2: Salida desde General Lemos | Horario Mural Invierno 2026 — Metrovías
A4: Estación | B4: {=INDEX(INPUT!$C:$C, 211+COLUMN()-2)} -> 03:12 | C4: {=INDEX(INPUT!$C:$C, 211+COLUMN()-2)} -> 04:15 | D4: {=INDEX(INPUT!$C:$C, 211+COLUMN()-2)} -> 05:30 | E4: {=INDEX(INPUT!$C:$C, 211+COLUMN()-2)} -> 06:20 | F4: {=INDEX(INPUT!$C:$C, 211+COLUMN()-2)} -> 06:55 | G4: {=INDEX(INPUT!$C:$C, 211+COLUMN()-2)} -> 07:25 | H4: {=INDEX(INPUT!$C:$C, 211+COLUMN()-2)} -> 07:55 | I4: {=INDEX(INPUT!$C:$C, 211+COLUMN()-2)} -> 08:25 | ... AM4: {=INDEX(INPUT!$C:$C, 211+COLUMN()-2)} -> 23:35
A5: General Lemos | B5: =B4 -> 03:12 | C5: =C4 -> 04:15 | D5: =D4 -> 05:30 | E5: =E4 -> 06:20 | F5: =F4 -> 06:55 | G5: =G4 -> 07:25 | H5: =H4 -> 07:55 | I5: =I4 -> 08:25 | ... AM5: =AM4 -> 23:35
A6: Sargento Cabral | B6: =TEXT(MOD(TIMEVALUE(B5)+2/1440,1),"HH:MM") -> 03:14 | C6: =TEXT(MOD(TIMEVALUE(C5)+2/1440,1),"HH:MM") -> 04:17 | D6: =TEXT(MOD(TIMEVALUE(D5)+2/1440,1),"HH:MM") -> 05:32 | E6: =TEXT(MOD(TIMEVALUE(E5)+2/1440,1),"HH:MM") -> 06:22 | F6: =TEXT(MOD(TIMEVALUE(F5)+2/1440,1),"HH:MM") -> 06:57 | G6: =TEXT(MOD(TIMEVALUE(G5)+2/1440,1),"HH:MM") -> 07:27 | H6: =TEXT(MOD(TIMEVALUE(H5)+2/1440,1),"HH:MM") -> 07:57 | I6: =TEXT(MOD(TIMEVALUE(I5)+2/1440,1),"HH:MM") -> 08:27 | ... AM6: =TEXT(MOD(TIMEVALUE(AM5)+2/1440,1),"HH:MM") -> 23:37
A7: Campo de Mayo | B7: =TEXT(MOD(TIMEVALUE(B5)+4/1440,1),"HH:MM") -> 03:16 | C7: =TEXT(MOD(TIMEVALUE(C5)+4/1440,1),"HH:MM") -> 04:19 | D7: =TEXT(MOD(TIMEVALUE(D5)+4/1440,1),"HH:MM") -> 05:34 | E7: =TEXT(MOD(TIMEVALUE(E5)+4/1440,1),"HH:MM") -> 06:24 | F7: =TEXT(MOD(TIMEVALUE(F5)+4/1440,1),"HH:MM") -> 06:59 | G7: =TEXT(MOD(TIMEVALUE(G5)+4/1440,1),"HH:MM") -> 07:29 | H7: =TEXT(MOD(TIMEVALUE(H5)+4/1440,1),"HH:MM") -> 07:59 | I7: =TEXT(MOD(TIMEVALUE(I5)+4/1440,1),"HH:MM") -> 08:29 | ... AM7: =TEXT(MOD(TIMEVALUE(AM5)+4/1440,1),"HH:MM") -> 23:39
A8: Teniente Agneta | B8: =TEXT(MOD(TIMEVALUE(B5)+5/1440,1),"HH:MM") -> 03:17 | C8: =TEXT(MOD(TIMEVALUE(C5)+5/1440,1),"HH:MM") -> 04:20 | D8: =TEXT(MOD(TIMEVALUE(D5)+5/1440,1),"HH:MM") -> 05:35 | E8: =TEXT(MOD(TIMEVALUE(E5)+5/1440,1),"HH:MM") -> 06:25 | F8: =TEXT(MOD(TIMEVALUE(F5)+5/1440,1),"HH:MM") -> 07:00 | G8: =TEXT(MOD(TIMEVALUE(G5)+5/1440,1),"HH:MM") -> 07:30 | H8: =TEXT(MOD(TIMEVALUE(H5)+5/1440,1),"HH:MM") -> 08:00 | I8: =TEXT(MOD(TIMEVALUE(I5)+5/1440,1),"HH:MM") -> 08:30 | ... AM8: =TEXT(MOD(TIMEVALUE(AM5)+5/1440,1),"HH:MM") -> 23:40
A9: Capitán Lozano | B9: =TEXT(MOD(TIMEVALUE(B5)+7/1440,1),"HH:MM") -> 03:19 | C9: =TEXT(MOD(TIMEVALUE(C5)+7/1440,1),"HH:MM") -> 04:22 | D9: =TEXT(MOD(TIMEVALUE(D5)+7/1440,1),"HH:MM") -> 05:37 | E9: =TEXT(MOD(TIMEVALUE(E5)+7/1440,1),"HH:MM") -> 06:27 | F9: =TEXT(MOD(TIMEVALUE(F5)+7/1440,1),"HH:MM") -> 07:02 | G9: =TEXT(MOD(TIMEVALUE(G5)+7/1440,1),"HH:MM") -> 07:32 | H9: =TEXT(MOD(TIMEVALUE(H5)+7/1440,1),"HH:MM") -> 08:02 | I9: =TEXT(MOD(TIMEVALUE(I5)+7/1440,1),"HH:MM") -> 08:32 | ... AM9: =TEXT(MOD(TIMEVALUE(AM5)+7/1440,1),"HH:MM") -> 23:42
A10: Sgto. Barruffaldi | B10: =TEXT(MOD(TIMEVALUE(B5)+9/1440,1),"HH:MM") -> 03:21 | C10: =TEXT(MOD(TIMEVALUE(C5)+9/1440,1),"HH:MM") -> 04:24 | D10: =TEXT(MOD(TIMEVALUE(D5)+9/1440,1),"HH:MM") -> 05:39 | E10: =TEXT(MOD(TIMEVALUE(E5)+9/1440,1),"HH:MM") -> 06:29 | F10: =TEXT(MOD(TIMEVALUE(F5)+9/1440,1),"HH:MM") -> 07:04 | G10: =TEXT(MOD(TIMEVALUE(G5)+9/1440,1),"HH:MM") -> 07:34 | H10: =TEXT(MOD(TIMEVALUE(H5)+9/1440,1),"HH:MM") -> 08:04 | I10: =TEXT(MOD(TIMEVALUE(I5)+9/1440,1),"HH:MM") -> 08:34 | ... AM10: =TEXT(MOD(TIMEVALUE(AM5)+9/1440,1),"HH:MM") -> 23:44
A11: Juan E. de la Salle | B11: =TEXT(MOD(TIMEVALUE(B5)+12/1440,1),"HH:MM") -> 03:24 | C11: =TEXT(MOD(TIMEVALUE(C5)+12/1440,1),"HH:MM") -> 04:27 | D11: =TEXT(MOD(TIMEVALUE(D5)+12/1440,1),"HH:MM") -> 05:42 | E11: =TEXT(MOD(TIMEVALUE(E5)+12/1440,1),"HH:MM") -> 06:32 | F11: =TEXT(MOD(TIMEVALUE(F5)+12/1440,1),"HH:MM") -> 07:07 | G11: =TEXT(MOD(TIMEVALUE(G5)+12/1440,1),"HH:MM") -> 07:37 | H11: =TEXT(MOD(TIMEVALUE(H5)+12/1440,1),"HH:MM") -> 08:07 | I11: =TEXT(MOD(TIMEVALUE(I5)+12/1440,1),"HH:MM") -> 08:37 | ... AM11: =TEXT(MOD(TIMEVALUE(AM5)+12/1440,1),"HH:MM") -> 23:47
A12: Ejército de los Andes | B12: =TEXT(MOD(TIMEVALUE(B5)+14/1440,1),"HH:MM") -> 03:26 | C12: =TEXT(MOD(TIMEVALUE(C5)+14/1440,1),"HH:MM") -> 04:29 | D12: =TEXT(MOD(TIMEVALUE(D5)+14/1440,1),"HH:MM") -> 05:44 | E12: =TEXT(MOD(TIMEVALUE(E5)+14/1440,1),"HH:MM") -> 06:34 | F12: =TEXT(MOD(TIMEVALUE(F5)+14/1440,1),"HH:MM") -> 07:09 | G12: =TEXT(MOD(TIMEVALUE(G5)+14/1440,1),"HH:MM") -> 07:39 | H12: =TEXT(MOD(TIMEVALUE(H5)+14/1440,1),"HH:MM") -> 08:09 | I12: =TEXT(MOD(TIMEVALUE(I5)+14/1440,1),"HH:MM") -> 08:39 | ... AM12: =TEXT(MOD(TIMEVALUE(AM5)+14/1440,1),"HH:MM") -> 23:49
A13: Rubén Darío | B13: =TEXT(MOD(TIMEVALUE(B5)+18/1440,1),"HH:MM") -> 03:30 | C13: =TEXT(MOD(TIMEVALUE(C5)+18/1440,1),"HH:MM") -> 04:33 | D13: =TEXT(MOD(TIMEVALUE(D5)+18/1440,1),"HH:MM") -> 05:48 | E13: =TEXT(MOD(TIMEVALUE(E5)+18/1440,1),"HH:MM") -> 06:38 | F13: =TEXT(MOD(TIMEVALUE(F5)+18/1440,1),"HH:MM") -> 07:13 | G13: =TEXT(MOD(TIMEVALUE(G5)+18/1440,1),"HH:MM") -> 07:43 | H13: =TEXT(MOD(TIMEVALUE(H5)+18/1440,1),"HH:MM") -> 08:13 | I13: =TEXT(MOD(TIMEVALUE(I5)+18/1440,1),"HH:MM") -> 08:43 | ... AM13: =TEXT(MOD(TIMEVALUE(AM5)+18/1440,1),"HH:MM") -> 23:53
A14: Jorge Newbery | B14: =TEXT(MOD(TIMEVALUE(B5)+20/1440,1),"HH:MM") -> 03:32 | C14: =TEXT(MOD(TIMEVALUE(C5)+20/1440,1),"HH:MM") -> 04:35 | D14: =TEXT(MOD(TIMEVALUE(D5)+20/1440,1),"HH:MM") -> 05:50 | E14: =TEXT(MOD(TIMEVALUE(E5)+20/1440,1),"HH:MM") -> 06:40 | F14: =TEXT(MOD(TIMEVALUE(F5)+20/1440,1),"HH:MM") -> 07:15 | G14: =TEXT(MOD(TIMEVALUE(G5)+20/1440,1),"HH:MM") -> 07:45 | H14: =TEXT(MOD(TIMEVALUE(H5)+20/1440,1),"HH:MM") -> 08:15 | I14: =TEXT(MOD(TIMEVALUE(I5)+20/1440,1),"HH:MM") -> 08:45 | ... AM14: =TEXT(MOD(TIMEVALUE(AM5)+20/1440,1),"HH:MM") -> 23:55
A15: Pedro Podestá | B15: =TEXT(MOD(TIMEVALUE(B5)+22/1440,1),"HH:MM") -> 03:34 | C15: =TEXT(MOD(TIMEVALUE(C5)+22/1440,1),"HH:MM") -> 04:37 | D15: =TEXT(MOD(TIMEVALUE(D5)+22/1440,1),"HH:MM") -> 05:52 | E15: =TEXT(MOD(TIMEVALUE(E5)+22/1440,1),"HH:MM") -> 06:42 | F15: =TEXT(MOD(TIMEVALUE(F5)+22/1440,1),"HH:MM") -> 07:17 | G15: =TEXT(MOD(TIMEVALUE(G5)+22/1440,1),"HH:MM") -> 07:47 | H15: =TEXT(MOD(TIMEVALUE(H5)+22/1440,1),"HH:MM") -> 08:17 | I15: =TEXT(MOD(TIMEVALUE(I5)+22/1440,1),"HH:MM") -> 08:47 | ... AM15: =TEXT(MOD(TIMEVALUE(AM5)+22/1440,1),"HH:MM") -> 23:57
A16: Martín Coronado | B16: =TEXT(MOD(TIMEVALUE(B5)+24/1440,1),"HH:MM") -> 03:36 | C16: =TEXT(MOD(TIMEVALUE(C5)+24/1440,1),"HH:MM") -> 04:39 | D16: =TEXT(MOD(TIMEVALUE(D5)+24/1440,1),"HH:MM") -> 05:54 | E16: =TEXT(MOD(TIMEVALUE(E5)+24/1440,1),"HH:MM") -> 06:44 | F16: =TEXT(MOD(TIMEVALUE(F5)+24/1440,1),"HH:MM") -> 07:19 | G16: =TEXT(MOD(TIMEVALUE(G5)+24/1440,1),"HH:MM") -> 07:49 | H16: =TEXT(MOD(TIMEVALUE(H5)+24/1440,1),"HH:MM") -> 08:19 | I16: =TEXT(MOD(TIMEVALUE(I5)+24/1440,1),"HH:MM") -> 08:49 | ... AM16: =TEXT(MOD(TIMEVALUE(AM5)+24/1440,1),"HH:MM") -> 23:59
A17: José M. Bosch | B17: =TEXT(MOD(TIMEVALUE(B5)+27/1440,1),"HH:MM") -> 03:39 | C17: =TEXT(MOD(TIMEVALUE(C5)+27/1440,1),"HH:MM") -> 04:42 | D17: =TEXT(MOD(TIMEVALUE(D5)+27/1440,1),"HH:MM") -> 05:57 | E17: =TEXT(MOD(TIMEVALUE(E5)+27/1440,1),"HH:MM") -> 06:47 | F17: =TEXT(MOD(TIMEVALUE(F5)+27/1440,1),"HH:MM") -> 07:22 | G17: =TEXT(MOD(TIMEVALUE(G5)+27/1440,1),"HH:MM") -> 07:52 | H17: =TEXT(MOD(TIMEVALUE(H5)+27/1440,1),"HH:MM") -> 08:22 | I17: =TEXT(MOD(TIMEVALUE(I5)+27/1440,1),"HH:MM") -> 08:52 | ... AM17: =TEXT(MOD(TIMEVALUE(AM5)+27/1440,1),"HH:MM") -> 00:02
A18: Tropezón | B18: =TEXT(MOD(TIMEVALUE(B5)+29/1440,1),"HH:MM") -> 03:41 | C18: =TEXT(MOD(TIMEVALUE(C5)+29/1440,1),"HH:MM") -> 04:44 | D18: =TEXT(MOD(TIMEVALUE(D5)+29/1440,1),"HH:MM") -> 05:59 | E18: =TEXT(MOD(TIMEVALUE(E5)+29/1440,1),"HH:MM") -> 06:49 | F18: =TEXT(MOD(TIMEVALUE(F5)+29/1440,1),"HH:MM") -> 07:24 | G18: =TEXT(MOD(TIMEVALUE(G5)+29/1440,1),"HH:MM") -> 07:54 | H18: =TEXT(MOD(TIMEVALUE(H5)+29/1440,1),"HH:MM") -> 08:24 | I18: =TEXT(MOD(TIMEVALUE(I5)+29/1440,1),"HH:MM") -> 08:54 | ... AM18: =TEXT(MOD(TIMEVALUE(AM5)+29/1440,1),"HH:MM") -> 00:04
A19: Lourdes | B19: =TEXT(MOD(TIMEVALUE(B5)+31/1440,1),"HH:MM") -> 03:43 | C19: =TEXT(MOD(TIMEVALUE(C5)+31/1440,1),"HH:MM") -> 04:46 | D19: =TEXT(MOD(TIMEVALUE(D5)+31/1440,1),"HH:MM") -> 06:01 | E19: =TEXT(MOD(TIMEVALUE(E5)+31/1440,1),"HH:MM") -> 06:51 | F19: =TEXT(MOD(TIMEVALUE(F5)+31/1440,1),"HH:MM") -> 07:26 | G19: =TEXT(MOD(TIMEVALUE(G5)+31/1440,1),"HH:MM") -> 07:56 | H19: =TEXT(MOD(TIMEVALUE(H5)+31/1440,1),"HH:MM") -> 08:26 | I19: =TEXT(MOD(TIMEVALUE(I5)+31/1440,1),"HH:MM") -> 08:56 | ... AM19: =TEXT(MOD(TIMEVALUE(AM5)+31/1440,1),"HH:MM") -> 00:06
A20: Fernández Moreno | B20: =TEXT(MOD(TIMEVALUE(B5)+33/1440,1),"HH:MM") -> 03:45 | C20: =TEXT(MOD(TIMEVALUE(C5)+33/1440,1),"HH:MM") -> 04:48 | D20: =TEXT(MOD(TIMEVALUE(D5)+33/1440,1),"HH:MM") -> 06:03 | E20: =TEXT(MOD(TIMEVALUE(E5)+33/1440,1),"HH:MM") -> 06:53 | F20: =TEXT(MOD(TIMEVALUE(F5)+33/1440,1),"HH:MM") -> 07:28 | G20: =TEXT(MOD(TIMEVALUE(G5)+33/1440,1),"HH:MM") -> 07:58 | H20: =TEXT(MOD(TIMEVALUE(H5)+33/1440,1),"HH:MM") -> 08:28 | I20: =TEXT(MOD(TIMEVALUE(I5)+33/1440,1),"HH:MM") -> 08:58 | ... AM20: =TEXT(MOD(TIMEVALUE(AM5)+33/1440,1),"HH:MM") -> 00:08
A21: Cnel. Fco. Lynch | B21: =TEXT(MOD(TIMEVALUE(B5)+35/1440,1),"HH:MM") -> 03:47 | C21: =TEXT(MOD(TIMEVALUE(C5)+35/1440,1),"HH:MM") -> 04:50 | D21: =TEXT(MOD(TIMEVALUE(D5)+35/1440,1),"HH:MM") -> 06:05 | E21: =TEXT(MOD(TIMEVALUE(E5)+35/1440,1),"HH:MM") -> 06:55 | F21: =TEXT(MOD(TIMEVALUE(F5)+35/1440,1),"HH:MM") -> 07:30 | G21: =TEXT(MOD(TIMEVALUE(G5)+35/1440,1),"HH:MM") -> 08:00 | H21: =TEXT(MOD(TIMEVALUE(H5)+35/1440,1),"HH:MM") -> 08:30 | I21: =TEXT(MOD(TIMEVALUE(I5)+35/1440,1),"HH:MM") -> 09:00 | ... AM21: =TEXT(MOD(TIMEVALUE(AM5)+35/1440,1),"HH:MM") -> 00:10
A22: Antonio Devoto | B22: =TEXT(MOD(TIMEVALUE(B5)+37/1440,1),"HH:MM") -> 03:49 | C22: =TEXT(MOD(TIMEVALUE(C5)+37/1440,1),"HH:MM") -> 04:52 | D22: =TEXT(MOD(TIMEVALUE(D5)+37/1440,1),"HH:MM") -> 06:07 | E22: =TEXT(MOD(TIMEVALUE(E5)+37/1440,1),"HH:MM") -> 06:57 | F22: =TEXT(MOD(TIMEVALUE(F5)+37/1440,1),"HH:MM") -> 07:32 | G22: =TEXT(MOD(TIMEVALUE(G5)+37/1440,1),"HH:MM") -> 08:02 | H22: =TEXT(MOD(TIMEVALUE(H5)+37/1440,1),"HH:MM") -> 08:32 | I22: =TEXT(MOD(TIMEVALUE(I5)+37/1440,1),"HH:MM") -> 09:02 | ... AM22: =TEXT(MOD(TIMEVALUE(AM5)+37/1440,1),"HH:MM") -> 00:12
A23: El Libertador | B23: =TEXT(MOD(TIMEVALUE(B5)+38/1440,1),"HH:MM") -> 03:50 | C23: =TEXT(MOD(TIMEVALUE(C5)+38/1440,1),"HH:MM") -> 04:53 | D23: =TEXT(MOD(TIMEVALUE(D5)+38/1440,1),"HH:MM") -> 06:08 | E23: =TEXT(MOD(TIMEVALUE(E5)+38/1440,1),"HH:MM") -> 06:58 | F23: =TEXT(MOD(TIMEVALUE(F5)+38/1440,1),"HH:MM") -> 07:33 | G23: =TEXT(MOD(TIMEVALUE(G5)+38/1440,1),"HH:MM") -> 08:03 | H23: =TEXT(MOD(TIMEVALUE(H5)+38/1440,1),"HH:MM") -> 08:33 | I23: =TEXT(MOD(TIMEVALUE(I5)+38/1440,1),"HH:MM") -> 09:03 | ... AM23: =TEXT(MOD(TIMEVALUE(AM5)+38/1440,1),"HH:MM") -> 00:13
A24: Dr. Fco. Beiró | B24: =TEXT(MOD(TIMEVALUE(B5)+39/1440,1),"HH:MM") -> 03:51 | C24: =TEXT(MOD(TIMEVALUE(C5)+39/1440,1),"HH:MM") -> 04:54 | D24: =TEXT(MOD(TIMEVALUE(D5)+39/1440,1),"HH:MM") -> 06:09 | E24: =TEXT(MOD(TIMEVALUE(E5)+39/1440,1),"HH:MM") -> 06:59 | F24: =TEXT(MOD(TIMEVALUE(F5)+39/1440,1),"HH:MM") -> 07:34 | G24: =TEXT(MOD(TIMEVALUE(G5)+39/1440,1),"HH:MM") -> 08:04 | H24: =TEXT(MOD(TIMEVALUE(H5)+39/1440,1),"HH:MM") -> 08:34 | I24: =TEXT(MOD(TIMEVALUE(I5)+39/1440,1),"HH:MM") -> 09:04 | ... AM24: =TEXT(MOD(TIMEVALUE(AM5)+39/1440,1),"HH:MM") -> 00:14
A25: Pedro N. Arata | B25: =TEXT(MOD(TIMEVALUE(B5)+42/1440,1),"HH:MM") -> 03:54 | C25: =TEXT(MOD(TIMEVALUE(C5)+42/1440,1),"HH:MM") -> 04:57 | D25: =TEXT(MOD(TIMEVALUE(D5)+42/1440,1),"HH:MM") -> 06:12 | E25: =TEXT(MOD(TIMEVALUE(E5)+42/1440,1),"HH:MM") -> 07:02 | F25: =TEXT(MOD(TIMEVALUE(F5)+42/1440,1),"HH:MM") -> 07:37 | G25: =TEXT(MOD(TIMEVALUE(G5)+42/1440,1),"HH:MM") -> 08:07 | H25: =TEXT(MOD(TIMEVALUE(H5)+42/1440,1),"HH:MM") -> 08:37 | I25: =TEXT(MOD(TIMEVALUE(I5)+42/1440,1),"HH:MM") -> 09:07 | ... AM25: =TEXT(MOD(TIMEVALUE(AM5)+42/1440,1),"HH:MM") -> 00:17
A26: José Artigas | B26: =TEXT(MOD(TIMEVALUE(B5)+44/1440,1),"HH:MM") -> 03:56 | C26: =TEXT(MOD(TIMEVALUE(C5)+44/1440,1),"HH:MM") -> 04:59 | D26: =TEXT(MOD(TIMEVALUE(D5)+44/1440,1),"HH:MM") -> 06:14 | E26: =TEXT(MOD(TIMEVALUE(E5)+44/1440,1),"HH:MM") -> 07:04 | F26: =TEXT(MOD(TIMEVALUE(F5)+44/1440,1),"HH:MM") -> 07:39 | G26: =TEXT(MOD(TIMEVALUE(G5)+44/1440,1),"HH:MM") -> 08:09 | H26: =TEXT(MOD(TIMEVALUE(H5)+44/1440,1),"HH:MM") -> 08:39 | I26: =TEXT(MOD(TIMEVALUE(I5)+44/1440,1),"HH:MM") -> 09:09 | ... AM26: =TEXT(MOD(TIMEVALUE(AM5)+44/1440,1),"HH:MM") -> 00:19
A27: Federico Lacroze | B27: =TEXT(MOD(TIMEVALUE(B5)+49/1440,1),"HH:MM") -> 04:01 | C27: =TEXT(MOD(TIMEVALUE(C5)+49/1440,1),"HH:MM") -> 05:04 | D27: =TEXT(MOD(TIMEVALUE(D5)+49/1440,1),"HH:MM") -> 06:19 | E27: =TEXT(MOD(TIMEVALUE(E5)+49/1440,1),"HH:MM") -> 07:09 | F27: =TEXT(MOD(TIMEVALUE(F5)+49/1440,1),"HH:MM") -> 07:44 | G27: =TEXT(MOD(TIMEVALUE(G5)+49/1440,1),"HH:MM") -> 08:14 | H27: =TEXT(MOD(TIMEVALUE(H5)+49/1440,1),"HH:MM") -> 08:44 | I27: =TEXT(MOD(TIMEVALUE(I5)+49/1440,1),"HH:MM") -> 09:14 | ... AM27: =TEXT(MOD(TIMEVALUE(AM5)+49/1440,1),"HH:MM") -> 00:24
A29: Fuente: Horario Mural Invierno 2026, Metrovías — metrovias.com.ar | Modificar la hora de salida en la fila de la estación de origen para recalcular todo el recorrido.

Sheet LC_Semana
A1: Tren Urquiza — Lunes a Viernes → Lemos
A2: Salida desde Federico Lacroze | Horario Mural Invierno 2026 — Metrovías
A4: Estación | B4: {=INDEX(INPUT!$C:$C, 252+COLUMN()-2)} -> 01:00 | C4: {=INDEX(INPUT!$C:$C, 252+COLUMN()-2)} -> 02:40 | D4: {=INDEX(INPUT!$C:$C, 252+COLUMN()-2)} -> 03:35 | E4: {=INDEX(INPUT!$C:$C, 252+COLUMN()-2)} -> 04:20 | F4: {=INDEX(INPUT!$C:$C, 252+COLUMN()-2)} -> 04:35 | G4: {=INDEX(INPUT!$C:$C, 252+COLUMN()-2)} -> 05:00 | H4: {=INDEX(INPUT!$C:$C, 252+COLUMN()-2)} -> 05:14 | I4: {=INDEX(INPUT!$C:$C, 252+COLUMN()-2)} -> 05:24 | ... CO4: {=INDEX(INPUT!$C:$C, 252+COLUMN()-2)} -> 23:50
A5: Federico Lacroze | B5: =B4 -> 01:00 | C5: =C4 -> 02:40 | D5: =D4 -> 03:35 | E5: =E4 -> 04:20 | F5: =F4 -> 04:35 | G5: =G4 -> 05:00 | H5: =H4 -> 05:14 | I5: =I4 -> 05:24 | ... CO5: =CO4 -> 23:50
A6: José Artigas | B6: =TEXT(MOD(TIMEVALUE(B5)+3/1440,1),"HH:MM") -> 01:03 | C6: =TEXT(MOD(TIMEVALUE(C5)+3/1440,1),"HH:MM") -> 02:43 | D6: =TEXT(MOD(TIMEVALUE(D5)+3/1440,1),"HH:MM") -> 03:38 | E6: =TEXT(MOD(TIMEVALUE(E5)+3/1440,1),"HH:MM") -> 04:23 | F6: =TEXT(MOD(TIMEVALUE(F5)+3/1440,1),"HH:MM") -> 04:38 | G6: =TEXT(MOD(TIMEVALUE(G5)+3/1440,1),"HH:MM") -> 05:03 | H6: =TEXT(MOD(TIMEVALUE(H5)+3/1440,1),"HH:MM") -> 05:17 | I6: =TEXT(MOD(TIMEVALUE(I5)+3/1440,1),"HH:MM") -> 05:27 | ... CO6: =TEXT(MOD(TIMEVALUE(CO5)+3/1440,1),"HH:MM") -> 23:53
A7: Pedro N. Arata | B7: =TEXT(MOD(TIMEVALUE(B5)+5/1440,1),"HH:MM") -> 01:05 | C7: =TEXT(MOD(TIMEVALUE(C5)+5/1440,1),"HH:MM") -> 02:45 | D7: =TEXT(MOD(TIMEVALUE(D5)+5/1440,1),"HH:MM") -> 03:40 | E7: =TEXT(MOD(TIMEVALUE(E5)+5/1440,1),"HH:MM") -> 04:25 | F7: =TEXT(MOD(TIMEVALUE(F5)+5/1440,1),"HH:MM") -> 04:40 | G7: =TEXT(MOD(TIMEVALUE(G5)+5/1440,1),"HH:MM") -> 05:05 | H7: =TEXT(MOD(TIMEVALUE(H5)+5/1440,1),"HH:MM") -> 05:19 | I7: =TEXT(MOD(TIMEVALUE(I5)+5/1440,1),"HH:MM") -> 05:29 | ... CO7: =TEXT(MOD(TIMEVALUE(CO5)+5/1440,1),"HH:MM") -> 23:55
A8: Dr. Fco. Beiró | B8: =TEXT(MOD(TIMEVALUE(B5)+7/1440,1),"HH:MM") -> 01:07 | C8: =TEXT(MOD(TIMEVALUE(C5)+7/1440,1),"HH:MM") -> 02:47 | D8: =TEXT(MOD(TIMEVALUE(D5)+7/1440,1),"HH:MM") -> 03:42 | E8: =TEXT(MOD(TIMEVALUE(E5)+7/1440,1),"HH:MM") -> 04:27 | F8: =TEXT(MOD(TIMEVALUE(F5)+7/1440,1),"HH:MM") -> 04:42 | G8: =TEXT(MOD(TIMEVALUE(G5)+7/1440,1),"HH:MM") -> 05:07 | H8: =TEXT(MOD(TIMEVALUE(H5)+7/1440,1),"HH:MM") -> 05:21 | I8: =TEXT(MOD(TIMEVALUE(I5)+7/1440,1),"HH:MM") -> 05:31 | ... CO8: =TEXT(MOD(TIMEVALUE(CO5)+7/1440,1),"HH:MM") -> 23:57
A9: El Libertador | B9: =TEXT(MOD(TIMEVALUE(B5)+9/1440,1),"HH:MM") -> 01:09 | C9: =TEXT(MOD(TIMEVALUE(C5)+9/1440,1),"HH:MM") -> 02:49 | D9: =TEXT(MOD(TIMEVALUE(D5)+9/1440,1),"HH:MM") -> 03:44 | E9: =TEXT(MOD(TIMEVALUE(E5)+9/1440,1),"HH:MM") -> 04:29 | F9: =TEXT(MOD(TIMEVALUE(F5)+9/1440,1),"HH:MM") -> 04:44 | G9: =TEXT(MOD(TIMEVALUE(G5)+9/1440,1),"HH:MM") -> 05:09 | H9: =TEXT(MOD(TIMEVALUE(H5)+9/1440,1),"HH:MM") -> 05:23 | I9: =TEXT(MOD(TIMEVALUE(I5)+9/1440,1),"HH:MM") -> 05:33 | ... CO9: =TEXT(MOD(TIMEVALUE(CO5)+9/1440,1),"HH:MM") -> 23:59
A10: Antonio Devoto | B10: =TEXT(MOD(TIMEVALUE(B5)+11/1440,1),"HH:MM") -> 01:11 | C10: =TEXT(MOD(TIMEVALUE(C5)+11/1440,1),"HH:MM") -> 02:51 | D10: =TEXT(MOD(TIMEVALUE(D5)+11/1440,1),"HH:MM") -> 03:46 | E10: =TEXT(MOD(TIMEVALUE(E5)+11/1440,1),"HH:MM") -> 04:31 | F10: =TEXT(MOD(TIMEVALUE(F5)+11/1440,1),"HH:MM") -> 04:46 | G10: =TEXT(MOD(TIMEVALUE(G5)+11/1440,1),"HH:MM") -> 05:11 | H10: =TEXT(MOD(TIMEVALUE(H5)+11/1440,1),"HH:MM") -> 05:25 | I10: =TEXT(MOD(TIMEVALUE(I5)+11/1440,1),"HH:MM") -> 05:35 | ... CO10: =TEXT(MOD(TIMEVALUE(CO5)+11/1440,1),"HH:MM") -> 00:01
A11: Cnel. Fco. Lynch | B11: =TEXT(MOD(TIMEVALUE(B5)+13/1440,1),"HH:MM") -> 01:13 | C11: =TEXT(MOD(TIMEVALUE(C5)+13/1440,1),"HH:MM") -> 02:53 | D11: =TEXT(MOD(TIMEVALUE(D5)+13/1440,1),"HH:MM") -> 03:48 | E11: =TEXT(MOD(TIMEVALUE(E5)+13/1440,1),"HH:MM") -> 04:33 | F11: =TEXT(MOD(TIMEVALUE(F5)+13/1440,1),"HH:MM") -> 04:48 | G11: =TEXT(MOD(TIMEVALUE(G5)+13/1440,1),"HH:MM") -> 05:13 | H11: =TEXT(MOD(TIMEVALUE(H5)+13/1440,1),"HH:MM") -> 05:27 | I11: =TEXT(MOD(TIMEVALUE(I5)+13/1440,1),"HH:MM") -> 05:37 | ... CO11: =TEXT(MOD(TIMEVALUE(CO5)+13/1440,1),"HH:MM") -> 00:03
A12: Fernández Moreno | B12: =TEXT(MOD(TIMEVALUE(B5)+15/1440,1),"HH:MM") -> 01:15 | C12: =TEXT(MOD(TIMEVALUE(C5)+15/1440,1),"HH:MM") -> 02:55 | D12: =TEXT(MOD(TIMEVALUE(D5)+15/1440,1),"HH:MM") -> 03:50 | E12: =TEXT(MOD(TIMEVALUE(E5)+15/1440,1),"HH:MM") -> 04:35 | F12: =TEXT(MOD(TIMEVALUE(F5)+15/1440,1),"HH:MM") -> 04:50 | G12: =TEXT(MOD(TIMEVALUE(G5)+15/1440,1),"HH:MM") -> 05:15 | H12: =TEXT(MOD(TIMEVALUE(H5)+15/1440,1),"HH:MM") -> 05:29 | I12: =TEXT(MOD(TIMEVALUE(I5)+15/1440,1),"HH:MM") -> 05:39 | ... CO12: =TEXT(MOD(TIMEVALUE(CO5)+15/1440,1),"HH:MM") -> 00:05
